Workbook
Name _1: #N/A
Name _3: #N/A
Name _4: #N/A
Name _DAT1: [1]Sheet1!#REF!
Name _DAT1: [2]Sheet1!#REF!
Name _DAT1: [1]Sheet1!#REF!
Name _DAT1: [1]Sheet1!#REF!
Name _DAT13: [1]Sheet1!#REF!
Name _DAT13: [2]Sheet1!#REF!
Name _DAT13: [1]Sheet1!#REF!
Name _DAT13: [1]Sheet1!#REF!
Name _DAT16: [1]Sheet1!#REF!
Name _DAT16: [2]Sheet1!#REF!
Name _DAT16: [1]Sheet1!#REF!
Name _DAT16: [1]Sheet1!#REF!
Name _DAT17: [1]Sheet1!#REF!
Name _DAT17: [2]Sheet1!#REF!
Name _DAT17: [1]Sheet1!#REF!
Name _DAT17: [1]Sheet1!#REF!
Name _DAT18: [1]Sheet1!#REF!
Name _DAT18: [2]Sheet1!#REF!
Name _DAT18: [1]Sheet1!#REF!
Name _DAT18: [1]Sheet1!#REF!
Name _DAT19: [1]Sheet1!#REF!
Name _DAT19: [2]Sheet1!#REF!
Name _DAT19: [1]Sheet1!#REF!
Name _DAT19: [1]Sheet1!#REF!
Name _DAT20: [1]Sheet1!#REF!
Name _DAT20: [2]Sheet1!#REF!
Name _DAT20: [1]Sheet1!#REF!
Name _DAT20: [1]Sheet1!#REF!
Name _DAT3: [1]Sheet1!#REF!
Name _DAT3: [2]Sheet1!#REF!
Name _DAT3: [1]Sheet1!#REF!
Name _DAT3: [1]Sheet1!#REF!
Name _DAT9: [1]Sheet1!#REF!
Name _DAT9: [2]Sheet1!#REF!
Name _DAT9: [1]Sheet1!#REF!
Name _DAT9: [1]Sheet1!#REF!
Name Assessment_Types: #REF!
Name Assessment_Types: #REF!
Name Assessment_Types: #REF!
Name Assessment_Types: #REF!
Name Assessment_Types: #REF!
Name Calqty: #REF!
Name Calqty: #REF!
Name Calqty: #REF!
Name Calqty: #REF!
Name Calqty: #REF!
Name Choices: [5]Sheet7!$A$19:$A$20
Name Choices: [5]Sheet7!$A$19:$A$20
Name Choices: [5]Sheet7!$A$19:$A$20
Name Choices: [6]Sheet7!$A$19:$A$20
Name code: #REF!
Name code: #REF!
Name code: #REF!
Name code: #REF!
Name code: #REF!
Name CODENO: '[7]BOM LIST 정리'!$D$7:$D$48
Name CODENO: '[8]BOM LIST 정리'!$D$7:$D$48

Sheet Cover.
E13: Supplier name
E14: Major Product
E15: Audit Object
E16: Date of Audit
E17: Auditor
E18: Grade
E19: Result
B22: M&C Electronics Vina

Sheet Result Report
B1: Quality Process Audit Result Report
C3: □ Audit Result
C4: Audit Object | F4: =[32]Cover.!G14 -> 0 | J4: Grade | M4: =[32]Cover.!G18 -> 0 | O4: Date of Audit
C5: Major Product | F5: =[32]Cover.!G15 -> 0 | J5: Auditor | M5: =[32]Cover.!G17 -> 0 | O5: Auditee
C8: □Scores and Grade by sector
C9: No | D9: evaluation sector | E9: Evaluation requiment | H9: Evaluation result | M9: note
E10: the whole | H10: Result | K10: Degree of Completion
C11: 1 | D11: Warehouse for Materials | E11: ='Check sheet'!E46 -> 12 | H11: ='Check sheet'!F53 -> 0 | K11: =H11/E11*100 -> 0
C12: 2 | D12: Material Inspection and Preparation | E12: ='Check sheet'!E47 -> 16 | H12: ='Check sheet'!F54 -> 0 | K12: =H12/E12*100 -> 0
C13: 3 | D13: Production Process | E13: ='Check sheet'!E48 -> 30 | H13: ='Check sheet'!F55 -> 0 | K13: =H13/E13*100 -> 0
C14: 4 | D14: Product Evaluation | E14: ='Check sheet'!E49 -> 29 | H14: ='Check sheet'!F56 -> 0 | K14: =H14/E14*100 -> 0
C15: 5 | D15: Packing and Shipment | E15: ='Check sheet'!E50 -> 13 | H15: ='Check sheet'!F57 -> 0 | K15: =H15/E15*100 -> 0
C16: Evaluation Score/Grade | E16: =SUM(H11:J15) -> 0 | H16: =IF(E16>=90,"A",IF(E16>=80,"B",IF(E16>=70,"C",IF(E16>=60,"D","E")))) -> E | K16: =IF(H16="A","Very Good",IF(H16="B"," Good",IF(H16="C","Need Improvement",IF(H16="D","Unsatisfactory","Unsatisfactory")))) -> Unsatisfactory
C18: □ Improvement object Status by type
C19: Classification | E19: Number of Cases
C20: Material Management
C21: Material Inspection and Preparation
C22: Production Process
C23: Product Evaluation
C24: Packing Management
C25: Total

Sheet Non-Conforming Item
B2: Quality Process Audit Non-Conforming Item
M5: 해결
M6: 미결
B8: Classification | C8: NO | D8: Problem | F8: Countermeasure for Improvement | J8: Confirmation Result | M8: Completion Status | N8: Reproducibility status
D9: Pointed-out Item | E9: Phenomenon | F9: Improvement Plan | G9: Pictrue | H9: Person in charge | I9: Schedule | J9: Confirmed content | K9: Schedule | L9: person in charge

Sheet Check sheet
C1: VENDOR QUALIFICATION CHECKSHEET | F1: Code of Form/ Mã số biểu mẫu | H1: PUR.04.00.07
F2: Effective Date/ Ngày hiệu lực | H2: 43466
C3: o The first evaluation/ Đánh giá lần đầu | E3: o The re-evaluation/ Đánh giá lại | F3: Page/ Tổng số trang | H3: 05
A4: Vendor code/ Mã vendor (ERP) | C4: Name of vendor/ Tên nhà cung cấp | E4: Address/ Địa chỉ | F4: Product type provide/ Loại sản phẩm cung cấp:
A5: P1908 | F5: o Raw Material/ NVL chính o Sub material/ Phụ liệu | H5: o Outsourcing Material/ NVL từ nguồn gia công
A6: P.I.C/ Người phụ trách | C6: Job title/ Chức vụ | D6: Department/ Phòng ban | E6: Email | F6: Phone No.
A9: CONTENT OF EVALUATION
A10: Section 1 - Warehouse for Materials | E10: Sub total (Score) | F10: =SUM(F13:F15) -> 12 | G10: =SUM(G13:G15) -> 0 | H10: COMMENT
E11: Achievement rate | F11: =F10/100 -> 0.12 | G11: =G10/100 -> 0
A12: Question Number | B12: Element | C12: Requirement | D12: VNM | E12: Rating Criteria | F12: Score | G12: Result
A13: 1 | B13: Standard | C13: Is the material storage standard established, and are the warehoused materials structuralized for first-in/first-out, and is there management tools? | D13: Tiêu chuẩn bảo quản vật liệu được thiết lập, có tiêu chuẩn first-in/first-out và có lịch sử quản lý không? | E13: Score 1: No standard for first-in/first-out, and materials in need of first-in/first-out are not managed. Score 2 : There is no management standard for first-in/first-out, but first-in/first-out is available for materias in need of it, or only the first-in/first-out management standard is retained. Score 3: There is first-in/first-out management standard, but required is partial improvement of the management object, or a state of management. Score 4 : The first-in/first-out management standard is established, and first-in, first-out process is in progress according to the management standard. | F13: 4
A14: 2 | B14: Environment | C14: 3.1 Are the material storing requirements defined? 3.2 Are the environmental temperature, humidity controlled? 3.3 Are the storing space well ventilated? 3.4 Are the risk of ignition prevented in the storing area? 3.5 Are all the materials be sealed? 3.6 Are fire extinguishers, sands be prepared in the storing area? 3.7 Are the leakage prevent solution be taken? 3.8 Are explosion-proof lamps, switches used in the storing area? | D14: 3.1 Các yêu cầu lưu trữ vật liệu được xác định? 3.2 Nhiệt độ môi trường, độ ẩm có được kiểm soát không? 3.3 Không gian lưu trữ có được thông gió tốt không? 3.4 Nguy cơ đánh lửa có được ngăn chặn trong khu vực lưu trữ không? 3.5 Tất cả các vật liệu có được niêm phong không? 3.6 Bình chữa cháy, cát có được chuẩn bị trong khu vực lưu trữ không? 3.7 Có phải là giải pháp ngăn chặn rò rỉ? 3.8 Đèn chống cháy nổ, công tắc được sử dụng trong khu vực lưu trữ? | E14: Score 1: : The environmental condition is not defined, nor is the temperature/humidity managed. Score 2: : Although the environmental condition is not defiend, temperature/humdity is managed, or the environmental condition for materials storage is established. Score 3: : The environmental condition is established, but a state of management needs to be improved. Score 4: : The environmental condition is established, and it is managed according to the established standard. | F14: 4
A15: 3 | B15: Layout | C15: Are the products classified by item in time of materials storage, and is there an identification mark for materials? | D15: Các nguyên vật liệu được phân loại theo mặt hàng trong thời gian lưu trữ , và có một dấu hiệu nhận dạng cho vật liệu không? | E15: Score 1: There is no standard for identification of the stored materials, and it's difficult to identify the materials in storage. Score 2 : Though there is no standard for identification of the materials in storage, the materials in storage are identified, or there is only the standard of identification management of the stored materials. Score 3: There is the identification standard of the materials in storage, but partial improvement is required. (difficulty in identifying some materials, etc.) Score 4: There is the identification standard of the materials in storage, and materials are identified according to the standard. | F15: 4
A16: Section 2- Material Inspection and Preparation | E16: Sub total (Score) | F16: =SUM(F19:F22) -> 16 | G16: =SUM(G19:G22) -> 0 | H16: COMMENT
E17: Achievement rate | F17: =15/100 -> 0.15 | G17: =G16/100 -> 0
A18: Question Number | B18: Element | C18: Question / Requirement | D18: VNM | E18: Rating Criteria | F18: Score | G18: Result
A19: 1 | B19: Material Inspection (WH) | C19: Are below critical quality control points of the material inspected in incoming? - Part Number and Lot Number - Maker/ Provider - Status of product - Packing condition - Quantity / Weight - Expiry Date | D19: Các điểm kiểm soát chất lượng quan trọng dưới đây của nguyên liệu có được đánh giá khi nhập vào? - Mã sản phẩm và số lot - Nhà sản xuất/ người cung ứng - Tình trạng của sản phẩm - Quy cách đóng gói - Số lượng / Trọng lượng - Ngày hết hạn | E19: Score 1 - More than 3 critical control point missed to be inspected in incoming. Score 2 - Some critical control points are inspected, but 2~3 critical control points missed. Score 3 - Some critical control points are inspected, but one critical control points missed. Score 4 - All critical control points are inspected in incoming | F19: 4
A20: 2 | B20: Material Inspection (IQC) | C20: Are below critical quality control points of material inspected ? - Spec - Appearance no damage, scratch, missing line, contamination, break line, etc. | D20: Các điểm kiểm soát chất lượng quan trọng của vật liệu có được kiểm tra? - Quy cách kỹ thuật, chất lượng sản phẩm -Ngoại quan: không có hư hại, trầy xước, thiếu dòng, nhiễm bẩn, đứt dòng, v.v. | E20: Score 1 - More than 3 critical control point missed to be inspected Score 2 - Some critical control points are inspected, but 2~3 critical control points missed. Score 3 - Some critical control points are inspected, but one critical control points missed. Score 4 - All critical control points are inspected | F20: 4
A21: 3 | B21: Material Inspection (IQC) | C21: - Does the supplier have a precision testing process and devices that measure the accuracy of the product? - Are the methods below are use? a. X-ray, b. Optic measurement c. Overlay | D21: - Nhà cung cấp có quy trình kiểm tra độ chính xác và các thiết bị đo đạc độ chính xác của sản phẩm không? - Các thiết bị nào được áp dụng để kiểm tra? a. Máy X-ray, b. Máy đo độ quang phủ c. Overlay | E21: Score 1. Do not meet requirement 1.1. Score 2. Meet requirement 1.1. Only use of c. Score 3. Meet requirement 1.1. Use of a or b. Score 4. Meet all requirements. | F21: 4
A22: 4 | B22: Pot Life Control for Partially Used Material | C22: - Is there a pot life control process for partially used material, one times material ? - Is there expiration date/time of the partially used material marked? - Are all these partially used materials used before the expiration date/time? | D22: - Có quy trình kiểm soát thời hạn sử dụng nguyên vật liệu đối với loại được sử dụng một phần hoặc nhiều lần hay không? - Có ngày / thời gian hết hạn của vật liệu được sử dụng một phần được đánh dấu không? - Tất cả những vật liệu được sử dụng một phần này có được sử dụng trước ngày / thời gian hết hạn không? | E22: Score 1 - Do not meet requirement 4.1 Score 2 - Meet requirement 4.1, but found multiple cases do not meet requirement 4.2 and/or 4.3 and/or 4.4. Score 3- Meet requirement 4.1, but found isolated case do not meet requirement 4.2 and/or 4.3 and/or 4.4. Score 4- Meet all requirements | F22: 4
A23: Section 3- Production Process | E23: Sub total (Score) | F23: =SUM(F26:F28) -> 30 | G23: =SUM(G26:G28) -> 0 | H23: COMMENT
E24: Achievement rate | F24: =F23/100 -> 0.3 | G24: =G23/100 -> 0
A25: Question Number | B25: Element | C25: Question / Requirement | E25: Rating Criteria | F25: Score | G25: Result
A26: 1 | B26: Material Inspection | C26: Are below critical quality control points of plastic film inspected in incoming? - Concentrations of toxic substances - Viscosity index - Tỷ trọng - Packing - Color | D26: Các điểm kiểm soát chất lượng quan trọng của phim nhựa dưới đây có được kiểm tra khi nhập? - Nồng độ các chất độc hại - Chỉ số độ nhớt - Proportion - Quy cách đóng gói - Màu sắc - Độ dẫn điện (Đối với vật liệu khay ESD) | E26: Score 2- Less than 3 of the listed critical control points missed. Score 4 - More than 3 of the listed critical control points missed. Score 6- Some critical control points are inspected, but missed any 2~3 of the listed critical control points. Score 8 - Some critical control points are inspected, but missed any 1 of the listed critical control points. Score 10 - All the listed critical control points are inspected in incoming. N/A - If supplier do not produce carton. Or if supplier produce corrugated board in house. | F26: 10
A27: 2 | B27: Key Process Parameter Control | C27: Are below key process parameters controlled in the manufacturing process? - Clean can - Preparing ( material, quantity, scale) - Mixing (speed, time) - Grinding metter (speed, time, particle size) | D27: Các thông số quy trình chính dưới đây có được kiểm soát trong quá trình sản xuất? - Làm sạch can - Pha chế ( Nguyên vật liệu, số lượng, cân) - Khuấy trộn (tốc độ, thời gian) - Máy nghiền (tốc độ, thời gian, kích thước hạt) | E27: Score 2- Less than 2 of the key process parameters missed to control. Score 4 - More than 3 of the key process parameters missed to control. Score 6 - Some listed key process parameters are controlled, but missed any 2~3 of the listed key parameters. Score 8 - Some listed key process parameters are controlled, but missed any 1 of the listed key parameters. Score 10 - All the listed key process parameters are controlled. N/A - If supplier do not produce carton. | F27: 10
A28: 3 | B28: Checking quality | C28: Are below critical quality control points of carton inspected? - Checking equipment - Checking components ( follow each of products) - Checking particle quantity (<=35 ea/1ml) - Actual rate of wastage | D28: Các thông số quy trình chính dưới đây có được kiểm soát trong quá trình sản xuất? - Thiết bị kiểm tra - Kiểm tra thành phần ( Theo từng sản phẩm) - Độ bền - Kiểm tra lượng hạt bụi (<=35 ea/1ml) - Tỷ lệ hao hụt | E28: Score 2 - None of the listed key process parameter is controlled. Score 4 - Some listed key process parameters are controlled, but missed any 3 of the listed key parameters. Score 6 - Some listed key process parameters are controlled, but missed any 2 of the listed key parameters. Score 8 - Some listed key process parameters are controlled, but missed any 1 of the listed key parameters. Score 10 - All the listed key process parameters are controlled. N/A - If supplier do not produce carton. | F28: 10
A29: Section 4- Product Evaluation (OQC) | E29: Sub total (Score) | F29: =SUM(F31:F37) -> 29 | G29: =SUM(G31:G37) -> 0 | H29: COMMENT
E30: Achievement rate | F30: =F29/100 -> 0.29 | G30: =G29/100 -> 0
A31: 1 | B31: Training | C31: Did an auditor receive an education about the measuring method, auditing method, and equipment use method , and get certified? | D31: Nhân viên kiểm tra có nhận được sự đào tạo về phương pháp đo lường, phương pháp kiểm tra và phương pháp sử dụng thiết bị và được chứng nhận không? | E31: Score 1: There is no auditor certiification standard, and an auditor has not been certified. Score 2: Though there is no auditor certification standard, the auditor certification has been invested, or the auditor certification standard is retained. Score 3: Though there is an auditor certification standard, the auditor certification system, identification management, and cyclic education management, etc are required to be partly improved. Score 4- There is the auditor certification standard, and certification evaluation/ identification management/ cyclic education, etc. are normally implemented. | F31: 4
A32: 2 | B32: Standard | C32: Are the audit standard and drawings are kept, and does the standard coincide with the products which are under auditing? | D32: Các tiêu chuẩn kiểm tra có phù hợpvà treo tại khu vực kiểm tra sản phẩm không ? | E32: Score 1: There are no audit standard management criteria, and an audit is done under an auditor's self-judgment without the audit standard and drawings. Score 2:Though the related standard is not available, an audit is performed according to the audit standard suited for products , or the criteria for the audit standard management are retained. Score 3: The audit standard is prepared and applied according to audit standard criteria, but audit items/method are required to be partly improved. Score 4: An audit is performed based on the audit standard prepared according to the audit standard management critera. | F32: 4
A33: 3 | B33: Layout | C33: Are the products/pre/post shipment inspection, and the storage place for rejected products under separately classified management, and marked? of pre/post audit for products is clearly handled. | D33: Khu vực kiểm tra có phân loại hàng chờ kiểm tra, hàng NG, hàng OK không? | E33: Score 1: There is no separate storage place, and products are stored in a state without distinction of pre/post audit. Score 2: Though there is no separate storage place for products, they are stored under classified management, or only the separate storage place is designated. Score 3: Products are kept in a separate storage place under classified management, but there are some products without distinction of pre/post audit. Score 4: Products are kept in a separate storage place under classified management, and distintion of pre/post audit for products is clearly handled. | F33: 4
A34: 4 | B34: Measuring equipmen | C34: Is the measuring equipment controlled and calibrated? | D34: Thiết bị đo có được quản lý và tiến hành hiệu chuẩn không ? | E34: Score 1 : There is no measuring instrument selection standard, and the accuracy of a measuring instrument is not compatible with the allowance of actual measurement items (ex. standard: xx.xx, measuring equipment: xx.x) Score 2 : There is the measuring instrument selection standard, or a measuring instrument in use is suitable for allowance measurement of actual products despite the absence of the standard. Score 3: There is the measuring instrument selection standard, but there exists a measuring instrument which is not selected according to the standard, or partial improvements are required, such as converiience of measurement, etc. Score 4: There is the the measuring instrument selection standard, and the accuracy of the measuring instrument in use is suited for measurement item allowance. (ex. standard: xx.xx, measuring equipment: xx.xx abnormal) | F34: 4
A35: 5 | B35: Follow customer | C35: Is the unacceptable item arising from a customer reflected in the management point of the audit process? | D35: Có quy trình xử lý khiếu nại của khách hàng không? | E35: Score 1: There is no system for revison by reflecting unacceptable item in the audit standard, and it is not reflected as the audit item. Score 2: Although there is no audit standard reflection system, it is reflected through the revision and addition of the audit item, or the system reflecting it in the audit standard is established. Score 3: Established is the system reflecting it in the audit item according to the countermeasures against an unacceptable item, but there are some cases of omissions, or partial improvement are required. Score 4: Etablished is the system reflecting it in the audit standard according to an unacceptable item, and actually such an unacceptable item is reflected in the audit standard. | F35: 4
A36: 6 | B36: Internal audit | C36: Is the receiving audit history managment register under record management?(receiving audit report, audit history, rejection status, corrective measures, and post-management, etc. ) | D36: Có tiến hành kiểm tra nội bộ không ? Các vấn đề cần khắc phục có tiến hành cải tiến kịp thời không? | E36: Score 1: There is no receiving audit history management standard, and history management is not in progress. Score 2: Although there is no receiving audit history management standard, the audit history is managed, or only the standard for history management is retained. Score 3: Although there is the receiving audit history management standard in time of the receiving audit, partial improvements of the history maintenance state(post-measure contents, etc.) are required. . Score 4: There is the receiving audit management standard, and all audit history records are maintained. | F36: 4
A37: 7 | B37: Product Evaluation | C37: Does the result of re-inspection of the products finished with the shippment inspection meet the standard? (Confirmation of the minimum 5 samples) (Inspection of the item relevant to the audit standard by sampling the minimum 5 pieces of the parts which passed the shippment inspection, and post-judgment by selecting additional items when necessary) | D37: Kiểm tra xác suất lại các sản phẩm đã hoàn thành có đạt tiêu chuẩn không? | E37: Score 1: As a result of the inspection, unacceptable parts account for more than 75%. Score 2: As a result of the inspection, unacceptable parts account for more than 50%. Score 3: As a result of the inspection, unacceptable parts account for 25~74%. Score 4: As a result of the inspection, unacceptable parts account for 1~24%. Score 5: As a result of the inspection, all parts in comparison with the standard are acceptable. | F37: 5
A38: Section 5- Packing and Shipment | E38: Sub total (Score) | F38: =SUM(F40:F43) -> 13 | G38: =SUM(G40:G43) -> 0 | H38: COMMENT
E39: Achievement rate | F39: =F38/100 -> 0.13 | G39: =G38/100 -> 0
A40: 1 | B40: Standard | C40: Are there packing work standard management criteria by part/item? If so, are they distributed to the relevant process, and under revised management? | D40: Có tiêu chuẩn quản lý đóng gói sản phẩm. Thực tế có tuân thủ không ? | E40: Score 1: There are no criteria for packing work standard management, nor is the packing standard used in time of packing. Score 2: Although there are no packing work management criteria, the packing standard by part/item is being used, or the criteria for packing work standard management are retained. Score 3: Though there are packing work standard management criteria, some of the packing guidelines and revised managment ,etc. are required to be partly improved. Score 4: There are packing work standard management criteria, and the standard is prepared, approved and distributed according to the criteria, and the standard is kept on the site to be applied. | F40: 4
A41: 2 | B41: FIFO | C41: Is there first-in, first-out for products in need of life-cycle management and history management of products, and are the products managed by the system? (color difference, before/after design change) | D41: Có tuân thủ quy định FIFO khi xuất hàng không? | E41: Score 1: There is no system for life-cycle management, or history management of a product, nor is first-in, first-out implemented. Score 2: Although there is no standard for product life-cycle & history management, first-in, first-out is implemented through the identification and maintenance of Lot and date of manfacturing, etc., or there are managment criteria. Score 3: There are the criteria of first-in, first-out for product life cycle & history management, but some are insufficient, or in need of improvements. Score 4: According to the criteria for first-in, first-out management of product, the first-in, first-out for actual products is implemented. | F41: 4
A42: 3 | B42: Environment | C42: Is the environmental condition of the warehouse under measurement control regularly? (temperature/humidity) | D42: Môi trường bảo quản thành phẩm có được quản lý không( nhiệt độ, độ ẩm ) | E42: Score 1 : The environmental condition is not defined, nor is the temperature/humidity managed. Score 2 : Although the environmental condition is not defiend, nor is the temperature/humidity managed, the environmental condition for materials storage is established. Score 3 : Although the environmental condition is not defiend, temperature/humdity is managed, or the environmental condition for materials storage is established. Score 4: The environmental condition is established, but a state of management needs to be improved. Score 5: The environmental condition is established, and it is managed according to the established standard. | F42: 5
...
