Workbook
Name _1: #N/A
Name _3: #N/A
Name _4: #N/A
Name _DAT1: [1]Sheet1!#REF!
Name _DAT1: [2]Sheet1!#REF!
Name _DAT1: [1]Sheet1!#REF!
Name _DAT1: [1]Sheet1!#REF!
Name _DAT13: [1]Sheet1!#REF!
Name _DAT13: [2]Sheet1!#REF!
Name _DAT13: [1]Sheet1!#REF!
Name _DAT13: [1]Sheet1!#REF!
Name _DAT16: [1]Sheet1!#REF!
Name _DAT16: [2]Sheet1!#REF!
Name _DAT16: [1]Sheet1!#REF!
Name _DAT16: [1]Sheet1!#REF!
Name _DAT17: [1]Sheet1!#REF!
Name _DAT17: [2]Sheet1!#REF!
Name _DAT17: [1]Sheet1!#REF!
Name _DAT17: [1]Sheet1!#REF!
Name _DAT18: [1]Sheet1!#REF!
Name _DAT18: [2]Sheet1!#REF!
Name _DAT18: [1]Sheet1!#REF!
Name _DAT18: [1]Sheet1!#REF!
Name _DAT19: [1]Sheet1!#REF!
Name _DAT19: [2]Sheet1!#REF!
Name _DAT19: [1]Sheet1!#REF!
Name _DAT19: [1]Sheet1!#REF!
Name _DAT20: [1]Sheet1!#REF!
Name _DAT20: [2]Sheet1!#REF!
Name _DAT20: [1]Sheet1!#REF!
Name _DAT20: [1]Sheet1!#REF!
Name _DAT3: [1]Sheet1!#REF!
Name _DAT3: [2]Sheet1!#REF!
Name _DAT3: [1]Sheet1!#REF!
Name _DAT3: [1]Sheet1!#REF!
Name _DAT9: [1]Sheet1!#REF!
Name _DAT9: [2]Sheet1!#REF!
Name _DAT9: [1]Sheet1!#REF!
Name _DAT9: [1]Sheet1!#REF!
Name Assessment_Types: #REF!
Name Calqty: #REF!
Name Choices: [5]Sheet7!$A$19:$A$20
Name code: #REF!
Name CODENO: '[6]BOM LIST 정리'!$D$7:$D$48
Name CODENO: '[7]BOM LIST 정리'!$D$7:$D$48
Name CONTRACT: #REF!
Name CONTRACT: #REF!
Name CONTRACT: #REF!
Name CONTRACT: #REF!
Name it: [8]!it
Name it: [9]!it
Name jan: #REF!
Name jan: #REF!
Name jan: #REF!
Name jan: #REF!
Name lll: [8]!lll
Name lll: [9]!lll
Name MRP: #REF!
Name MRP: #REF!
Name MRP: #REF!

Sheet Cover.
E13: Supplier name
E14: Major Product
E15: Audit Object
E16: Date of Audit
E17: Auditor
E18: Grade
E19: Result
B22: M&C Electronics Vina

Sheet Result Report
B1: Quality Process Audit Result Report
C3: □ Audit Result
C4: Audit Object | F4: =Cover.!G14 -> 0 | J4: Grade | M4: =Cover.!G18 -> 0 | O4: Date of Audit | Q4: 43777
C5: Major Product | F5: =Cover.!G15 -> 0 | J5: Auditor | M5: =Cover.!G17 -> 0 | O5: Auditee | Q5: Ms Hậu
C8: □Scores and Grade by sector
C9: No | D9: evaluation sector | E9: Evaluation requiment | H9: Evaluation result | M9: note
E10: the whole | H10: Result | K10: Degree of Completion
C11: 1 | D11: Material Management | E11: ='Checksheet QPA'!E51 -> 12 | K11: =H11/E11*100 -> 0
C12: 2 | D12: Material Inspection and Preparation | E12: ='Checksheet QPA'!E52 -> 20 | K12: =H12/E12*100 -> 0
C13: 3 | D13: Production Process | E13: ='Checksheet QPA'!E53 -> 28 | K13: =H13/E13*100 -> 0
C14: 4 | D14: Product Evaluation | E14: ='Checksheet QPA'!E54 -> 28 | K14: =H14/E14*100 -> 0
C15: 5 | D15: Packing Management | E15: ='Checksheet QPA'!E55 -> 12 | K15: =H15/E15*100 -> 0
C16: Evaluation Score/Grade | E16: =SUM(H11:J15) -> 0 | H16: =IF(E16>=90,"A",IF(E16>=80,"B",IF(E16>=70,"C",IF(E16>=60,"D","E")))) -> E | K16: =IF(H16="A","Very Good",IF(H16="B"," Good",IF(H16="C","Need Improvement",IF(H16="D","Unsatisfactory","Unsatisfactory")))) -> Unsatisfactory
C18: □ Improvement object Status by type
C19: Classification | E19: Number of Cases
C20: Material Management
C21: Material Inspection and Preparation
C22: Production Process
C23: Product Evaluation
C24: Packing Management
C25: Total

Sheet Non-Conforming Item
B2: Quality Process Audit Non-Conforming Item
M5: 해결
M6: 미결
B8: Classification | C8: NO | D8: Problem | F8: Countermeasure for Improvement | J8: Confirmation Result | M8: Completion Status | N8: Reproducibility status
D9: Pointed-out Item | E9: Phenomenon | F9: Improvement Plan | G9: Picture | H9: Person in charge | I9: Schedule | J9: Confirmed content | K9: Schedule | L9: person in charge

Sheet Checksheet QPA
C1: VENDOR QUALIFICATION CHECKSHEET | F1: Code of Form/ Mã số biểu mẫu | H1: PUR.04.00.07
F2: Effective Date/ Ngày hiệu lực | H2: 42036
C3: The first evaluation/ Đánh giá lần đầu | E3: o The re-evaluation/ Đánh giá lại | F3: Page/ Tổng số trang | H3: 06
A4: Vendor code/ Mã vendor (ERP) | C4: Name of vendor/ Tên nhà cung cấp | E4: Address/ Địa chỉ | F4: Product type provide/ Loại sản phẩm cung cấp:
C5: Công ty TNHH SAMEUN electronics vina | E5: Lô FJ-16,FJ-17 KCN Song Khê, Nội Hoàng(Khu phía nam),Xã Tiền Phong,Huyện Yên Dũng,Tỉnh Bắc Giang. | F5: o Raw Material/ NVL chính o Sub material/ Phụ liệu | H5: þOutsourcing Material/ NVL từ nguồn gia côngþ
A6: P.I.C/ Người phụ trách | C6: Job title/ Chức vụ | D6: Department/ Phòng ban | E6: Email | F6: Phone No.
A7: Mr Thống | C7: Quản lý | D7: QC | E7: havanthong1986@gmail.com | F7: 0984095563
A9: CONTENT OF EVALUATION
A10: Section 1 - Warehouse for Materials | E10: Sub total (Score) | F10: =SUM(F13:F15) -> 12 | G10: =SUM(G13:G15) -> 0 | H10: COMMENT
E11: Achievement rate | F11: =F10/100 -> 0.12 | G11: =G10/100 -> 0
A12: Question Number | B12: Element | C12: Requirement | D12: VNM | E12: Rating Criteria | F12: Score | G12: Result
A13: 1 | B13: Standard | C13: Is the material storage standard established, and are the warehoused materials structuralized for first-in/first-out, and is there management tools? | D13: Tiêu chuẩn bảo quản vật liệu được thiết lập, có tiêu chuẩn first-in/first-out và có lịch sử quản lý không? | E13: Score 1: No standard for first-in/first-out, and materials in need of first-in/first-out are not managed. Score 2 : There is no management standard for first-in/first-out, but first-in/first-out is available for materias in need of it, or only the first-in/first-out management standard is retained. Score 3: There is first-in/first-out management standard, but required is partial improvement of the management object, or a state of management. Score 4 : The first-in/first-out management standard is established, and first-in, first-out process is in progress according to the management standard. | F13: 4
A14: 2 | B14: Environment | C14: Is the environmental condition of the warehouse under measurement control regularly? (temperature/humidity) | D14: Môi trường bảo quản thành phẩm có được quản lý không( nhiệt độ, độ ẩm ) | E14: Score 1: : The environmental condition is not defined, nor is the temperature/humidity managed. Score 2: : Although the environmental condition is not defiend, temperature/humdity is managed, or the environmental condition for materials storage is established. Score 3: : The environmental condition is established, but a state of management needs to be improved. Score 4: : The environmental condition is established, and it is managed according to the established standard. | F14: 4
A15: 3 | B15: Layout | C15: Are the products classified by item in time of materials storage, and is there an identification mark for materials? | D15: Các nguyên vật liệu được phân loại theo mặt hàng trong thời gian lưu trữ , và có một dấu hiệu nhận dạng cho vật liệu không? | E15: Score 1: There is no standard for identification of the stored materials, and it's difficult to identify the materials in storage. Score 2 : Though there is no standard for identification of the materials in storage, the materials in storage are identified, or there is only the standard of identification management of the stored materials. Score 3: There is the identification standard of the materials in storage, but partial improvement is required. (difficulty in identifying some materials, etc.) Score 4: There is the identification standard of the materials in storage, and materials are identified according to the standard. | F15: 4
A16: Section 2- Material Inspection and Preparation | E16: Sub total (Score) | F16: =SUM(F19:F23) -> 20 | G16: =SUM(G19:G23) -> 0 | H16: COMMENT
E17: Achievement rate | F17: =F16/100 -> 0.2 | G17: =G16/100 -> 0
A18: Question Number | B18: Element | C18: Question / Requirement | D18: VNM | E18: Rating Criteria | F18: Score | G18: Result
A19: 1 | B19: Material Inspection procedure | C19: - Is there a process to control materials? - Is there a standard for testing materials? | D19: - Có quy trình kiểm soát nguyên vật liệu hay không? - Có tiêu chuẩn kiểm tra nguyên vật liệu không? | E19: Score 1. Do not meet requirement 1.1. Score 2. Meet requirement 1.1. Only use of c. Score 3. Meet requirement 1.1. Use of a or b. Score 4. Meet all requirements. | F19: 4
A20: 2 | B20: Material Inspection (WH) | C20: Are below critical quality control points of the material inspected in incoming? - Part Number and Lot Number - Maker/ Provider - Status of product - Packing condition - Quantity / Weight | D20: Các điểm kiểm soát chất lượng quan trọng dưới đây của nguyên liệu có được đánh giá khi nhập vào? - Mã sản phẩm và số lot - Nhà sản xuất/ người cung ứng/ ngày hết hạn - Tình trạng của sản phẩm - Quy cách đóng gói - Số lượng / Trọng lượng | E20: Score 1 - More than 3 critical control point missed to be inspected in incoming. Score 2 - Some critical control points are inspected, but 2~3 critical control points missed. Score 3 - Some critical control points are inspected, but one critical control points missed. Score 4 - All critical control points are inspected in incoming | F20: 4
A21: 3 | B21: Material Inspection (IQC) | C21: Are below critical quality control points of material inspected ? - Appearance - Mill sheet -Passed MSDS, SGS certification. | D21: Các điểm kiểm soát chất lượng quan trọng của vật liệu có được kiểm tra? -Ngoại quan - Phân tích thành phần - Chứng nhận MSDS, SGS.. | E21: Score 1. Do not meet requirement 1.1. Score 2. Meet requirement 1.1. Only use of c. Score 3. Meet requirement 1.1. Use of a or b. Score 4. Meet all requirements. | F21: 4
A22: 4 | B22: Material Inspection (IQC) | C22: - Do inspectors receive training in inspection and compliance methods? | D22: - Nhân viên kiểm tra có nhận được sự đào tạo về phương pháp kiểm tra và tuân thủ hay không? | E22: Score 1. Do not meet requirement 1.1. Score 2. Meet requirement 1.1. Only use of c. Score 3. Meet requirement 1.1. Use of a or b. Score 4. Meet all requirements. | F22: 4
A23: 5 | B23: Material Inspection (IQC) | C23: - Are test standards set at the product inspection area? | D23: - Các tiêu chuẩn kiểm tra có được treo tại khu vực kiểm tra sản phẩm không ? | E23: Score 1. Do not meet requirement 1.1. Score 2. Meet requirement 1.1. Only use of c. Score 3. Meet requirement 1.1. Use of a or b. Score 4. Meet all requirements. | F23: 4
A24: Section 3- Production Process | E24: Sub total (Score) | F24: =SUM(F27:F33) -> 28 | G24: =SUM(G27:G33) -> 0 | H24: COMMENT
E25: Achievement rate | F25: =F24/100 -> 0.28 | G25: =G24/100 -> 0
A26: Question Number | B26: Element | C26: Question / Requirement | E26: Rating Criteria | F26: Score | G26: Result
A27: 1 | B27: Painting | C27: -Is expiry of paints managed? 1. No expiry management criteria is in place, and expired materials are mixed with valid ones 2. No expiry management criteria is in place, but no expired materials are found due to proper expiry management; or the expiry management criteria is in place 3. The expiry management criteria is in place, but improvement is required in the management of expired materials list and expiration dates as well as the implementation. 4. The items are managed in accordance with the standard, where the list of expired materials and dates are managed and expired materials are discarded. | D27: -Hết hạn sơn được quản lý không? 0.Không có tiêu chí quản lý hết hạn và các tài liệu đã hết hạn được trộn với các tài liệu hợp lệ. 1. Không có tiêu chuẩn quản lý hết hạn, nhưng không tìm thấy tài liệu hết hạn do quản lý hết hạn thích hợp; hoặc các tiêu chí quản lý hết hạn. 2. Các tiêu chuẩn quản lý hết hạn được đưa ra, nhưng cần phải cải tiến trong việc quản lý danh sách các tài liệu hết hạn và ngày hết hạn cũng như việc thực hiện. 3. Các hạng mục được quản lý theo tiêu chuẩn, trong đó danh mục nguyên vật liệu và ngày hết hạn được loại bỏ và hết hạn sử dụng. | E27: Score 1. Do not meet requirement 1.1. Score 2. Meet requirement 1.1. Only use of c. Score 3. Meet requirement 1.1. Use of a or b. Score 4. Meet all requirements. | F27: 4
A28: 2 | B28: Painting | C28: -Are paint mixing ratio/stiring conditions managed? . 1 : No relevant criteria is in place, while the ratio is not controlled. . 2 : No relevant criteria is in place, but the ratio is managed; or the standard to manage the ratio is in place. . 3 : The standard to manage the ratio is in place, but improvement is required with regard to the accuracy of the method to manage the ratio (highly likely to yield errors) . 4 : The standard to manage the ratio is in place and the mixing is performed using a verified meters, with the ratio maintained. | D28: Tỷ lệ pha trộn sơn / điều kiện bắn được quản lý không? . 1: Không có tiêu chí liên quan nào được đưa ra, trong khi tỷ lệ này không được kiểm soát. . 2: Không có tiêu chí liên quan nào được đưa ra, nhưng tỷ lệ được quản lý; hoặc tiêu chuẩn để quản lý tỷ lệ được đưa ra. . 3: Tiêu chuẩn để quản lý tỷ lệ được áp dụng, nhưng cần phải cải thiện liên quan đến độ chính xác của phương pháp để quản lý tỷ lệ (rất có thể gây ra lỗi) . 4: Tiêu chuẩn để quản lý tỷ lệ được đặt ra và việc trộn được thực hiện bằng cách sử dụng đồng hồ đã được xác minh, với tỷ lệ được duy trì. | E28: Score 1. Do not meet requirement 1.1. Score 2. Meet requirement 1.1. Only use of c. Score 3. Meet requirement 1.1. Use of a or b. Score 4. Meet all requirements. | F28: 4
A29: 3 | B29: Painting | C29: Is the mixed paint applied within a predefined period of time (must use within 8hrs when a hardener agent was added) . 0 : Mixing time and application period are not observed, and there is no application criteria. . 1 : No application time criteria is in place, but the application time after mixing is properly observed; or the application time criteria is in place. . 2 : The criteria to apply paints after mixing is in place, but improvement is required in terms of its implementation and management. . 3 : The criteria to manage mixing and application time, and the application is performed in accordance with the criteria.r shoots? | D29: - Sơn hỗn hợp có được sử dụng trong khoảng thời gian định trước hay không (phải sử dụng trong vòng 8 giờ sau khi thêm chất làm cứng) 0: Không có thời gian trộn và thời gian ứng dụng được quan sát, và không có tiêu chí ứng dụng nào được áp dụng. . 1: Không có tiêu chuẩn thời gian áp dụng, nhưng thời gian áp dụng sau khi trộn đã được tuân thủ chính xác hoặc tiêu chuẩn thời gian áp dụng được áp dụng. . 2: Các tiêu chuẩn để áp dụng sơn sau khi trộn đã được thiết lập, nhưng cần cải thiện trong việc thực hiện và quản lý. . 3: Một tiêu chuẩn để quản lý thời gian trộn và ứng dụng, và quản trị theo tiêu chuẩn. | E29: Score 1. Do not meet requirement 1.1. Score 2. Meet requirement 1.1. Only use of c. Score 3. Meet requirement 1.1. Use of a or b. Score 4. Meet all requirements. | F29: 4
A30: 4 | B30: Painting | C30: Is there any effective standard applied to compressed air used for paintings, and are the cleanliness, moisture removal and pressure properly managed? . 1 : Air is not filtered with no moisture removal in place, and the pressure ill-controlled, so compressed air with foreign materials is used; or the relevant standard is not in place. . 2 : No compressed air-related standard is in place, but clean air with no foreign materials is used and/or the pressure is proplerly controlled; or the relevant standard is in place. . 3 : The compressed air-related standard is in place, but improvement is required to further remove foreign materials and to better manage the pressures. . 4 : The compressed air-related standard is in place and observed so that clean air with no foreign materials is used while the pressure is controlled through calibrated meters. | D30: Có một tiêu chuẩn hiệu quả cho khí nén phù hợp cho sơn không? Là sạch sẽ, tỷ lệ hút ẩm và áp lực được quản lý đúng cách không? . 1: Không lọc, không loại bỏ độ ẩm, kiểm soát áp suất kém, do đó khí nén có chất lạ được sử dụng hoặc không có tiêu chuẩn liên quan. . 2: Không có tiêu chuẩn nào liên quan đến khí nén được thiết lập, nhưng không khí sạch được sử dụng mà không có vật lạ và / hoặc áp suất được kiểm soát hợp lý; hoặc có các tiêu chuẩn liên quan. . 3: Các tiêu chuẩn liên quan đến khí nén được đưa ra, nhưng cần cải thiện để tiếp tục loại bỏ vật lạ và áp lực kiểm soát tốt hơn. . 4: Các tiêu chuẩn liên quan đến khí nén được đưa ra và được quan sát là sử dụng không khí sạch mà không có vật lạ trong khi kiểm soát áp suất qua máy đo hiệu chuẩn. | E30: Score 1. Do not meet requirement 1.1. Score 2. Meet requirement 1.1. Only use of c. Score 3. Meet requirement 1.1. Use of a or b. Score 4. Meet all requirements. | F30: 4
A31: 5 | B31: Painting | C31: Does the SOW specify the drying time and method after painting and are they observed? (temp., time, amount, etc.) . 0 : No standard specifying drying time and mothod is in place, and the practices are performed in an arbitrary manner. . 1 : No standard specifying drying time and mothod is in place, but the methods and times are consistently managed; or the relevant standard is in place. . 2 : There is a standard specifying drying time and mothod in place, but improvement is required for the provisions and implementation. . 3 : The drying time and method are specified in the standard and the compliance has been objectively verified (e.g., by logging start/end times) | D31: SOW có chỉ định thời gian và phương pháp sấy sau khi sơn không, có được quan sát không? (nhiệt độ, thời gian, số lượng, v.v.) . 0: Không có tiêu chuẩn về thời gian và phương pháp sấy, và nó được vận hành theo bất kỳ cách nào. . 1: Không có tiêu chuẩn về thời gian và phương pháp sấy, nhưng phương pháp và thời gian được quản lý một cách nhất quán hoặc các tiêu chuẩn có liên quan được đưa ra. . 2: Có một tiêu chuẩn quy định thời gian và phương pháp sấy, nhưng cần phải cải thiện các quy định và thực hiện. . 3: Thời gian và phương pháp sấy được chỉ định trong tiêu chuẩn và việc tuân thủ đã được xác minh một cách khách quan (ví dụ: bằng cách ghi lại thời gian bắt đầu / kết thúc) | E31: Score 1. Do not meet requirement 1.1. Score 2. Meet requirement 1.1. Only use of c. Score 3. Meet requirement 1.1. Use of a or b. Score 4. Meet all requirements. | F31: 4
A32: 6 | B32: Painting | C32: -Are criteria for testing paint thickness and adhesion in place, and is there any relevant inspection performed? - Is there a management of dust concentration and thickness of paint? - Are the speed of conveying and spraying parameters managed? | D32: -Có tiêu chuẩn kiểm tra để kiểm tra độ dày và độ bám dính của sơn không?, và nó đã được kiểm tra chưa? - Có quản lý nồng độ bụi và độ dầy của sơn hay không? - Các thông số tốc độ chuyền, thời gian phun có được quản lý không? | E32: Score 1. Do not meet requirement 1.1. Score 2. Meet requirement 1.1. Only use of c. Score 3. Meet requirement 1.1. Use of a or b. | F32: 4
A33: 7 | B33: Painting | C33: Are painted items stored in a good condition? (no exposure to sunlight, rainfall, snow and condensation) . 1 : No standards to manage dried painted items is in place, and painted items are ill-managed (e.g. storing outdoor without packaging) . 2 : No management standard is in place, but the painted items are well-managed; or the management standard is in place. . 3 : The management standard is in place, but improvement is required in some aspects. . 4 : In accordance with the relevant standards, the painted items are stored in a clean indoor place with no exposure to sunlights and weather and packaged when shipped. | D33: Các mặt hàng sơn được lưu trữ tốt không? (Không tiếp xúc với ánh sáng mặt trời, mưa, tuyết và ngưng tụ) . 1: Không có tiêu chuẩn để quản lý các dự án sơn khô và các dự án sơn được quản lý kém (ví dụ: được lưu trữ ngoài trời mà không có bao bì) . 2: Không có tiêu chuẩn quản lý, nhưng dự án sơn được quản lý tốt, hoặc các tiêu chuẩn quản lý được đưa ra. . 3: Các tiêu chuẩn quản lý đã được phát triển, nhưng vẫn cần cải thiện trong một số lĩnh vực. . 4: Theo các tiêu chuẩn có liên quan, các vật dụng được sơn nên được lưu trữ ở nơi trong nhà sạch sẽ, và không nên tiếp xúc với ánh sáng mặt trời và thời tiết, và đóng gói trong quá trình vận chuyển. | E33: Score 01- No any of the listed critical control point is inspected after die cutting. Score 2- Some critical control points are inspected, but missed any 2 of the listed critical control points. Score 3 - Some critical control points are inspected, but missed any 1 of the listed critical control points. Score 4 - All the listed critical control points are inspected after die cutting. | F33: 4
A34: Section 4- Product Evaluation (OQC) | E34: Sub total (Score) | F34: =SUM(F36:F42) -> 28 | G34: =SUM(G36:G42) -> 0 | H34: COMMENT
A35: Question Number | B35: Element | C35: Question / Requirement | E35: Achievement rate | F35: =F34/100 -> 0.28 | G35: =G34/100 -> 0
A36: 1 | B36: Training | C36: Did an auditor receive an education about the measuring method, auditing method, and equipment use method , and get certified? | D36: Nhân viên kiểm tra có nhận được sự đào tạo về phương pháp đo lường, phương pháp kiểm tra và phương pháp sử dụng thiết bị và được chứng nhận không? | E36: Score 0: There is no auditor certiification standard, and an auditor has not been certified. Score 1: Though there is no auditor certification standard, the auditor certification has been invested, or the auditor certification standard is retained. Score 2: Though there is an auditor certification standard, the auditor certification system, identification management, and cyclic education management, etc are required to be partly improved. Score 3- There is the auditor certification standard, and certification evaluation/ identification management/ cyclic education, etc. are normally implemented. | F36: 4
A37: 2 | B37: Standard | C37: Are the audit standard and drawings are kept, and does the standard coincide with the products which are under auditing? | D37: Các tiêu chuẩn kiểm tra có phù hợpvà treo tại khu vực kiểm tra sản phẩm không ? | E37: Score 0: There are no audit standard management criteria, and an audit is done under an auditor's self-judgment without the audit standard and drawings. Score 1:Though the related standard is not available, an audit is performed according to the audit standard suited for products , or the criteria for the audit standard management are retained. Score 2: The audit standard is prepared and applied according to audit standard criteria, but audit items/method are required to be partly improved. Score 3: An audit is performed based on the audit standard prepared according to the audit standard management critera. | F37: 4
A38: 3 | B38: Layout | C38: Are the products/pre/post shipment inspection, and the storage place for rejected products under separately classified management, and marked? of pre/post audit for products is clearly handled. | D38: Khu vực kiểm tra có phân loại hàng chờ kiểm tra, hàng NG, hàng OK không? | E38: Score 0: There is no separate storage place, and products are stored in a state without distinction of pre/post audit. Score 1: Though there is no separate storage place for products, they are stored under classified management, or only the separate storage place is designated. Score 2: Products are kept in a separate storage place under classified management, but there are some products without distinction of pre/post audit. Score 3: Products are kept in a separate storage place under classified management, and distintion of pre/post audit for products is clearly handled. | F38: 4
A39: 4 | B39: Measuring equipmen | C39: Is the measuring equipment controlled and calibrated? | D39: Thiết bị đo có được quản lý và tiến hành hiệu chuẩn không ? | E39: Score 0 : There is no measuring instrument selection standard, and the accuracy of a measuring instrument is not compatible with the allowance of actual measurement items (ex. standard: xx.xx, measuring equipment: xx.x) Score 1 : There is the measuring instrument selection standard, or a measuring instrument in use is suitable for allowance measurement of actual products despite the absence of the standard. Score 2: There is the measuring instrument selection standard, but there exists a measuring instrument which is not selected according to the standard, or partial improvements are required, such as converiience of measurement, etc. Score 3: There is the the measuring instrument selection standard, and the accuracy of the measuring instrument in use is suited for measurement item allowance. (ex. standard: xx.xx, measuring equipment: xx.xx abnormal) | F39: 4
A40: 5 | B40: Follow customer | C40: Is the unacceptable item arising from a customer reflected in the management point of the audit process? | D40: Có quy trình xử lý khiếu nại của khách hàng không? | E40: Score 0: There is no system for revison by reflecting unacceptable item in the audit standard, and it is not reflected as the audit item. Score 1: Although there is no audit standard reflection system, it is reflected through the revision and addition of the audit item, or the system reflecting it in the audit standard is established. Score 2: Established is the system reflecting it in the audit item according to the countermeasures against an unacceptable item, but there are some cases of omissions, or partial improvement are required. Score 3: Etablished is the system reflecting it in the audit standard according to an unacceptable item, and actually such an unacceptable item is reflected in the audit standard. | F40: 4
A41: 6 | B41: Internal audit | C41: Is the receiving audit history managment register under record management?(receiving audit report, audit history, rejection status, corrective measures, and post-management, etc. ) | D41: Có tiến hành kiểm tra nội bộ không ? Các vấn đề cần khắc phục có tiến hành cải tiến kịp thời không? | E41: Score 0: There is no receiving audit history management standard, and history management is not in progress. Score 1: Although there is no receiving audit history management standard, the audit history is managed, or only the standard for history management is retained. Score 2: Although there is the receiving audit history management standard in time of the receiving audit, partial improvements of the history maintenance state(post-measure contents, etc.) are required. . Score 3: There is the receiving audit management standard, and all audit history records are maintained. | F41: 4
...
