Workbook
Name __CON1: #REF!
Name __CON2: #REF!
Name __NET2: #REF!
Name _1: #N/A
Name _2: #REF!
Name _3: #N/A
Name _4: #N/A
Name _CON1: #REF!
Name _CON2: #REF!
Name _DAT1: [1]Sheet1!#REF!
Name _DAT1: [2]Sheet1!#REF!
Name _DAT1: [2]Sheet1!#REF!
Name _DAT13: [1]Sheet1!#REF!
Name _DAT13: [2]Sheet1!#REF!
Name _DAT13: [2]Sheet1!#REF!
Name _DAT16: [1]Sheet1!#REF!
Name _DAT16: [2]Sheet1!#REF!
Name _DAT16: [2]Sheet1!#REF!
Name _DAT17: [1]Sheet1!#REF!
Name _DAT17: [2]Sheet1!#REF!
Name _DAT17: [2]Sheet1!#REF!
Name _DAT18: [1]Sheet1!#REF!
Name _DAT18: [2]Sheet1!#REF!
Name _DAT18: [2]Sheet1!#REF!
Name _DAT19: [1]Sheet1!#REF!
Name _DAT19: [2]Sheet1!#REF!
Name _DAT19: [2]Sheet1!#REF!
Name _DAT20: [1]Sheet1!#REF!
Name _DAT20: [2]Sheet1!#REF!
Name _DAT20: [2]Sheet1!#REF!
Name _DAT3: [1]Sheet1!#REF!
Name _DAT3: [2]Sheet1!#REF!
Name _DAT3: [2]Sheet1!#REF!
Name _DAT9: [1]Sheet1!#REF!
Name _DAT9: [2]Sheet1!#REF!
Name _DAT9: [2]Sheet1!#REF!
Name _NET2: #REF!
Name a277Print_Titles: #REF!
Name aerg: #N/A
Name Assessment_Types: #REF!
Name Assessment_Types: #REF!
Name Assessment_Types: #REF!
Name Assessment_Types: #REF!
Name Assessment_Types: #REF!
Name B_Isc: #REF!
Name bang_gia: #REF!
Name BOQ: #REF!
Name BVCISUMMARY: #REF!
Name Calqty: #REF!
Name Calqty: #REF!
Name Calqty: #REF!
Name Calqty: #REF!
Name Calqty: #REF!
Name Choices: [5]Sheet7!$A$19:$A$20
Name Choices: [5]Sheet7!$A$19:$A$20
Name Choices: [5]Sheet7!$A$19:$A$20
Name Choices: [5]Sheet7!$A$19:$A$20
Name Co: #REF!
Name code: #REF!
Name code: #REF!

Sheet Cover.
E13: Supplier name
E14: Major Product
E15: Audit Object
E16: Date of Audit
E17: Auditor
E18: Grade
E19: Result
B22: M&C Electronics Vina

Sheet Result Report
B1: Quality Process Audit Result Report
C3: □ Audit Result
C4: Audit Object | F4: =[30]Cover.!G14 -> 0 | J4: Grade | M4: =[30]Cover.!G18 -> 0 | O4: Date of Audit
C5: Major Product | F5: =[30]Cover.!G15 -> 0 | J5: Auditor | M5: =[30]Cover.!G17 -> 0 | O5: Auditee
C8: □Scores and Grade by sector
C9: No | D9: evaluation sector | E9: Evaluation requiment | H9: Evaluation result | M9: note
E10: the whole | H10: Result | K10: Degree of Completion
C11: 1 | D11: Warehouse for Materials | E11: =Checksheet!E75 -> 9 | H11: =Checksheet!G10 -> 0 | K11: =H11/E11*100 -> 0
C12: 2 | D12: Tooling Development in House | E12: =+Checksheet!E76 -> NA | H12: NA | K12: =H12/E12*100 -> #VALUE!
C13: 3 | D13: Tooling Development Outsourcing | E13: =Checksheet!E77 -> 10 | H13: =Checksheet!G26 -> 0 | K13: =H13/E13*100 -> 0
C14: 4 | D14: Tooling Management | E14: =Checksheet!E78 -> 21 | H14: =Checksheet!G33 -> 0 | K14: =H14/E14*100 -> 0
C15: 5 | D15: Metal Stamping | E15: =Checksheet!E79 -> 30 | H15: =Checksheet!G43 -> 0 | K15: =H15/E15*100 -> 0
C16: 6 | D16: Product Evaluation | E16: =Checksheet!E80 -> 21 | H16: =Checksheet!G56 -> 0 | K16: =H16/E16*100 -> 0
C17: 7 | D17: Packing and Shipment | E17: =Checksheet!E81 -> 9 | H17: =Checksheet!G66 -> 0 | K17: =H17/E17*100 -> 0
C18: Evaluation Score/Grade | E18: =SUM(H11:J17) -> 0 | H18: =IF(E18>=90,"A",IF(E18>=80,"B",IF(E18>=70,"C",IF(E18>=60,"D","E")))) -> E | K18: =IF(H18="A","Very Good",IF(H18="B"," Good",IF(H18="C","Need Improvement",IF(H18="D","Unsatisfactory","Unsatisfactory")))) -> Unsatisfactory
C20: □ Improvement object Status by type
C21: Classification | E21: Number of Cases
C22: Material Management
C23: Material Inspection and Preparation
C24: Production Process
C25: Product Evaluation
C26: Packing Management
C27: Total

Sheet Non-Conforming Item
B2: Quality Process Audit Non-Conforming Item
M5: 해결
M6: 미결
B8: Classification | C8: NO | D8: Problem | F8: Countermeasure for Improvement | J8: Confirmation Result | M8: Completion Status | N8: Reproducibility status
D9: Pointed-out Item | E9: Phenomenon | F9: Improvement Plan | G9: Pictrue | H9: Person in charge | I9: Schedule | J9: Confirmed content | K9: Schedule | L9: person in charge

Sheet Checksheet
C1: QUALITY PROCESS AUDIT CHECK SHEET | F1: Code of Form/ Mã số biểu mẫu | H1: PUR.04.00.07
F2: Effective Date/ Ngày hiệu lực | H2: 43466
C3: o The first evaluation/ Đánh giá lần đầu | E3: The re-evaluation/ Đánh giá lại | F3: Page/ Tổng số trang | H3: 8
A4: Vendor code/ Mã vendor (ERP) | C4: Name of vendor/ Tên nhà cung cấp | E4: Address/ Địa chỉ | F4: Product type provide/ Loại sản phẩm cung cấp:
F5: Raw Material/ NVL chính o Sub material/ Phụ liệu | H5: Outsourcing Material/ NVL từ nguồn gia công
A6: P.I.C/ Người phụ trách | C6: Job title/ Chức vụ | D6: Department/ Phòng ban | E6: Email | F6: Phone No.
A9: CONTENT OF EVALUATION
A10: Section 1 - Warehouse for Materials | E10: Sub total (Score) | F10: =SUM(F13:F15) -> 9 | G10: =SUM(G13:G15) -> 0
E11: Achievement rate | F11: =F10/100 -> 0.09 | G11: =G10/100 -> 0
A12: Question Number | B12: Element | C12: Requirement | D12: VNM | E12: Rating Criteria | F12: Score | G12: Result | H12: Comment
A13: 1 | B13: Standard | C13: Is the material storage standard established, and are the warehoused materials structuralized for first-in/first-out, and is there management tools? | D13: Tiêu chuẩn bảo quản vật liệu được thiết lập, có tiêu chuẩn first-in/first-out và có lịch sử quản lý không? | E13: Score 0: No standard for first-in/first-out, and materials in need of first-in/first-out are not managed. Score 1 : There is no management standard for first-in/first-out, but first-in/first-out is available for materias in need of it, or only the first-in/first-out management standard is retained. Score 2: There is first-in/first-out management standard, but required is partial improvement of the management object, or a state of management. Score 3 : The first-in/first-out management standard is established, and first-in, first-out process is in progress according to the management standard. | F13: 3
A14: 2 | B14: Environment | C14: Is the environmental condition of the warehouse under measurement control regularly? (temperature/humidity) | D14: Môi trường bảo quản thành phẩm có được quản lý không( nhiệt độ, độ ẩm ) | E14: Score 0 : The environmental condition is not defined, nor is the temperature/humidity managed. Score 1 : Although the environmental condition is not defiend, temperature/humdity is managed, or the environmental condition for materials storage is established. Score 2 : The environmental condition is established, but a state of management needs to be improved. Score 3 : The environmental condition is established, and it is managed according to the established standard. | F14: 3
A15: 3 | B15: Layout | C15: Are the products classified by item in time of materials storage, and is there an identification mark for materials? | D15: Các nguyên vật liệu được phân loại theo mặt hàng trong thời gian lưu trữ , và có một dấu hiệu nhận dạng cho vật liệu không? | E15: Score 0: There is no standard for identification of the stored materials, and it's difficult to identify the materials in storage. Score 1 : Though there is no standard for identification of the materials in storage, the materials in storage are identified, or there is only the standard of identification management of the stored materials. Score 2: There is the identification standard of the materials in storage, but partial improvement is required. (difficulty in identifying some materials, etc.) Score 3: There is the identification standard of the materials in storage, and materials are identified according to the standard. | F15: 3
A16: Section 2- Tooling Development in House | E16: Sub total (Score) | F16: =SUM(F19:F25) -> 0 | G16: =SUM(G19:G25) -> 0
E17: Achievement rate | F17: =F16/100 -> 0 | G17: =G16/100 -> 0
A18: Question Number | B18: Element | C18: Question / Requirement | D18: VNM | E18: Rating Criteria | F18: Score | G18: Result | H18: Comment
A19: 1 | B19: Tooling Design Process | C19: 1.1 Is there a tooling design guideline defined? 1.2 Are the tooling design guideline followed in the actual tooling design activities? 1.3 Are the tooling designers trained on the guideline? 1.4 Are the lesson learns from previous tooling design history incorporated to the design guideline? Notes: it is acceptable if supplier combine the tooling design guideline, tooling verification process and tooling change process in one document | D19: 1.1 Có hướng dẫn thiết kế dụng cụ được xác định không? 1.2 Hướng dẫn thiết kế dụng cụ có tuân theo các hoạt động thiết kế dụng cụ thực tế không? 1.3 Các nhà thiết kế dụng cụ có được đào tạo theo hướng dẫn không? 1.4 Bài học rút ra từ lịch sử thiết kế dụng cụ trước đây có được kết hợp với hướng dẫn thiết kế không? Lưu ý: có thể chấp nhận được nếu nhà cung cấp kết hợp hướng dẫn thiết kế dụng cụ, quy trình xác minh dụng cụ và quy trình thay đổi công cụ trong một tài liệu | E19: Score 0 - Do not meet requirement 1.1. Score 1 - Meet requirement 1.1. But do not meet requirement 1.2 and/or 1.3. Score 2 - Meet requirements 1.1, 1.2 and 1.3. But do not meet requirement 1.4. Score 3 - Meet all requirements N/A - If supplier do not develop the tooling in house. | F19: N/A
A20: 2 | B20: DFM for Tooling | C20: 2.1 Is there a DFM process for tooling design in place? 2.2 Is the DFM reviewed and approved by customer before tooling creating? 2.3 Does the DFM cover all the critical characteristics of product? | D20: 2.1 Có quy trình DFM để thiết kế dụng cụ không? 2.2 DFM có được khách hàng xem xét và phê duyệt trước khi tạo công cụ không? 2.3 DFM có bao gồm tất cả các đặc tính quan trọng của sản phẩm không? | E20: Score 0 - Do not meet requirement 2.1. Score 1 - Meet requirement 2.1. But do not meet requirement 2.2. Score 2 - Meet requirement 2.1 and 2.2. But do not meet requirement 2.3. Score 3 - Meet all requirements. N/A - If supplier do not develop the tooling in house. | F20: N/A
A21: 3 | B21: Part 3D Unfolding Analysis | C21: 3.1 Is there a defined part 3D unfolding analysis process in place? 3.2 Do the actual part 3D unfolding analysis activities actually follow the defined process? | D21: 3.1 Có một quy trình phân tích trải tấm 3D được xác định tại chỗ không? 3.2 Các hoạt động phân tích trải tấm 3D thực tế có thực sự tuân theo quy trình đã xác định không? | E21: Score 0 - Do not meet requirement 3.1. Score 1 - Meet requirement 3.1. But find multiple cases do not meet requirement 3.2. Score 2 - Meet requirement 3.1. But find isolated case do not meet requirement 3.2. Score 3 - Meet all requirements. N/A - If supplier do not develop the tooling in house. | F21: N/A
A22: 4 | B22: Part Layout Design | C22: 4.1 Is there a defined part layout design process in place? 4.2 Do the actual part layout design activities actually follow the defined process? | D22: 4.1 Có một quy trình thiết kế bố trí layout được xác định tại chỗ không? 4.2 Các hoạt động thiết kế bố trí layout thực tế có thực sự tuân theo quy trình xác định không? | E22: Score 0 - Do not meet requirement 4.1. Score 1 - Meet requirement 4.1. But find multiple cases do not meet requirement 4.2. Score 2 - Meet requirement 4.1. But find isolated case do not meet requirement 4.2. Score 3 - Meet all requirements. N/A - If supplier do not develop the tooling in house. | F22: N/A
A23: 5 | B23: Tooling Drawing Review | C23: 5.1 Is there a tooling drawing review process in place? 5.2 Is the tooling drawing internally reviewed by authorized people? 5.3 If customer approval required, is the tooling drawing reviewed by customer? | D23: 5.1 Có quy trình xem xét bản vẽ dụng cụ tại chỗ không? 5.2 Bản vẽ công cụ có được xem xét nội bộ bởi những người được ủy quyền không? 5.3 Nếu cần có sự chấp thuận của khách hàng, bản vẽ dụng cụ có được khách hàng xem xét không? | E23: Score 0 - Do not meet requirement 5.1. Score 1 - Meet requirement 5.1. But do not meet requirement 5.2. Score 2 - Meet requirements 5.1 and 5.2. But do not meet requirement 5.3. Score 3 - Meet all requirements. N/A - If supplier do not develop the tooling in house. | F23: N/A
A24: 6 | B24: Tooling Customized Parts Measurement | C24: 6.1 Are the tooling customized parts measured after manufacturing? 6.2 Are all customized tooling parts included? 6.3 Are the measurement report traceable? Notes: It is not required for the off-the-shelf tooling parts, such as: pins, screws, standard punches, etc. | D24: 6.1 Các bộ phận tùy chỉnh dụng cụ được đo sau khi sản xuất? 6.2 Có bao gồm tất cả các bộ phận dụng cụ tùy chỉnh? 6.3 Báo cáo đo lường có thể truy nguyên được không? Lưu ý: Không bắt buộc đối với các bộ phận dụng cụ ngoài giá, chẳng hạn như: ghim, ốc vít, đục lỗ tiêu chuẩn, v.v. | E24: Score 0 - Do not meet requirement 6.1. Score 1 - Meet requirement 6.1. But do not meet requirement 6.2. Score 2 - Meet requirement 6.1, and 6.2 But do not meet requirement 6.3. Score 3 - Meet all requirements. N/A - If supplier do not develop the tooling in house. | F24: N/A
A25: 7 | B25: Tooling Verification | C25: 7.1 Is there a tooling verification process in place? 7.2 Are the tooling verification actually implemented and the verification results meet the requirements before tooling release? Remark: a). Tooling verification requirements may include but not limited to: trial run test, FAIR, Cpk, product appearance review, etc. Depends on customer requirements and internal requirements. b). 1 tooling count as 1 case. | D25: 7.1 Có quy trình xác minh dụng cụ tại chỗ không? 7.2 Việc xác minh dụng cụ có thực sự được thực hiện không và kết quả xác minh có đáp ứng các yêu cầu trước khi phát hành công cụ không? Ghi chú: a). Các yêu cầu xác minh dụng cụ có thể bao gồm nhưng không giới hạn ở: thử nghiệm chạy thử, FAIR, Cpk, đánh giá ngoại hình sản phẩm, vv Tùy thuộc vào yêu cầu của khách hàng và yêu cầu nội bộ. b). 1 dụng cụ được tính là 1 trường hợp. | E25: Score 0 - Do not meet requirement 7.1. Score 1 - Meet requirement 7.1. But find multiple cases do not meet requirement 7.2. Score 2 - Meet requirement 7.1. But find isolated case do not meet requirement 7.2. Score 3 - Meet all requirements. N/A - If supplier do not develop the tooling in house. | F25: N/A
A26: Section 3- Tooling Development Outsourcing | E26: Sub total (Score) | F26: =SUM(F29:F32) -> 10 | G26: =SUM(G29:G32) -> 0
E27: Achievement rate | F27: =F26/100 -> 0.1 | G27: =G26/100 -> 0
A28: Question Number | B28: Element | C28: Question / Requirement | D28: VNM | E28: Rating Criteria | F28: Score | G28: Result | H28: Comment
A29: 1 | B29: Requirements Communicate to Tooling Sub-Supplier | C29: 1.1 Is there a process of communicating the requirements to tooling sub-suppliers in place? 1.2 Are all critical requirements communicated to tooling sub-supplier? Notes: Critical requirements may include but not limited to: product drawing, product cosmetic requirements, tooling type (single station or progressive tooling), tonnage of each stamping station, tooling life, delivery schedule, tooling verification requirements, etc. | D29: 1.1 Có một quy trình truyền đạt các yêu cầu cho các nhà cung cấp phụ tại chỗ không? 1.2 Có phải tất cả các yêu cầu quan trọng được truyền đạt tới nhà cung cấp phụ dụng cụ? Lưu ý: Các yêu cầu quan trọng có thể bao gồm nhưng không giới hạn ở: bản vẽ sản phẩm, yêu cầu ngoại quan của sản phẩm, loại dụng cụ (trạm đơn hoặc dụng cụ tiến bộ), trọng tải của từng trạm dập, tuổi thọ dụng cụ, lịch giao hàng, yêu cầu xác minh dụng cụ, v.v. | E29: Score 0 - Do not meet requirement 1.1. Score 1 - Meet requirement 1.1. But multiple cases do not meet requirement 1.2. Score 2 - Meet requirement 1.1. But isolated case do not meet requirement 1.2. Score 3 - Meet all requirements N/A - If supplier do not develop the tooling outsourcing. | F29: 2
A30: 2 | B30: DFM Review | C30: 2.1 Is there a process to review the tooling DFM from tooling sub-supplier? 2.2 Are the tooling DFMs actually reviewed and approved by supplier (who purchase the tooling and use it for production)? 2.3 Are the tooling DFMs submitted to and approved by customer? 2.4 Does the DFM cover all the critical characteristics of product? | D30: 2.1 Có quy trình để xem xét DFM dụng cụ từ nhà cung cấp phụ dụng cụ không? 2.2 Các DFM dụng cụ có thực sự được xem xét và phê duyệt bởi nhà cung cấp (những người mua dụng cụ này và sử dụng nó cho sản xuất)? 2.3 Các DFM dụng cụ có được đệ trình và phê duyệt bởi khách hàng không? 2.4 DFM có bao gồm tất cả các đặc tính quan trọng của sản phẩm không? | E30: Score 0 - Do not meet requirement 2.1. Score 1 - Meet requirement 2.1. But do not meet requirement 2.2 and/or 2.3. Score 2 - Meet requirements 2.1, 2.2 and 2.3. But do not meet requirement 2.4. Score 3 - Meet all requirements N/A - If supplier do not develop the tooling outsourcing. | F30: 2
A31: 3 | B31: Tooling Customized Parts Measurement | C31: 6.1 Are the tooling customized parts measurement report reviewed? 6.2 Are all customized tooling parts included? 6.3 Are the measurement report well maintained? Notes: It is not required for the off-the-shelf tooling parts, such as: pins, screws, standard punches, etc. | D31: 6.1 Báo cáo đo lường các bộ phận tùy chỉnh dụng cụ có được xem xét không? 6.2 Có bao gồm tất cả các bộ phận dụng cụ tùy chỉnh? 6.3 Báo cáo đo có được duy trì tốt không? Lưu ý: Không bắt buộc đối với các bộ phận dụng cụ ngoài giá, chẳng hạn như: ghim, ốc vít, đục lỗ tiêu chuẩn, v.v. | E31: Score 0 - Do not meet requirement 6.1. Score 1 - Meet requirement 6.1. But do not meet requirement 6.2. Score 2 - Meet requirement 6.1 and 6.2. But do not meet requirement 6.3. Score 3 - Meet all requirements. N/A - If supplier do not develop the tooling in house. | F31: 3
A32: 4 | B32: Tooling Verification | C32: 4.1 Is there a process to verify the tooling before deliver the tooling from sub tooling supplier to production? 4.2 Are the tooling verification actually implemented and the verification results meet the requirements before tooling release? Remark: a). Tooling verification requirements may include but not limited to: trial run test, FAIR, Cpk, product appearance review, etc. Depends on customer requirements and internal requirements. b). 1 tooling count as 1 case. | D32: 4.1 Có quy trình xác minh dụng cụ trước khi chuyển dụng cụ từ nhà cung cấp dụng cụ phụ sang sản xuất không? 4.2 Việc xác minh dụng cụ có thực sự được thực hiện và kết quả xác minh có đáp ứng các yêu cầu trước khi phát hành công cụ không? Ghi chú: a). Các yêu cầu xác minh dụng cụ có thể bao gồm nhưng không giới hạn ở: thử nghiệm chạy thử, FAIR, Cpk, đánh giá ngoại hình sản phẩm, vv Tùy thuộc vào yêu cầu của khách hàng và yêu cầu nội bộ. b). 1 dụng cụ được tính là 1 trường hợp. | E32: Score 0 - Do not meet requirement 4.1. Score 1 - Meet requirement 4.1. But find multiple cases do not meet requirement 4.2. Score 2 - Meet requirement 4.1. But find isolated case do not meet requirement 4.2. Score 3 - Meet all requirements. N/A - If supplier do not develop the tooling outsourcing. | F32: 3
A33: Section 4- Tooling Management | E33: Sub total (Score) | F33: =SUM(F36:F42) -> 21 | G33: =SUM(G36:G42) -> 0
E34: Achievement rate | F34: =F33/100 -> 0.21 | G34: =G33/100 -> 0
A35: Question Number | B35: Element | C35: Question / Requirement | E35: Rating Criteria | F35: Score | G35: Result | H35: Comment
A36: 1 | B36: Tooling Release to Production | C36: 1.1 Is there a tooling release process in place? 1.2 Have all the tooling release requirements been met before the tooling release to production? 1.3 Is the tooling release document signed by authorized people before release to production? 1.4 Are the necessary tooling development records transferred to and maintained by tooling maintenance department. Notes: a). Tooling release requirements may include but not limited to: DFM has been approved by customer, tooling drawing has been approved, tooling verification result meet all requirements, etc. b). Tooling development records may include but not limited to: tooling drawing, tooling verification reports, tooling EC records in development stage, samples, etc. | D36: 1.1 Có quy trình phát hành dụng cụ tại chỗ không? 1.2 Tất cả các yêu cầu phát hành dụng cụ đã được đáp ứng trước khi phát hành dụng cụ vào sản xuất chưa? 1.3 Tài liệu phát hành dụng cụ có chữ ký của người được ủy quyền trước khi phát hành vào sản xuất không? 1.4 Các hồ sơ phát triển dụng cụ cần thiết được chuyển đến và duy trì bởi bộ phận bảo trì dụng cụ. Ghi chú: a). Yêu cầu phát hành dụng cụ có thể bao gồm nhưng không giới hạn ở: DFM đã được khách hàng chấp thuận, bản vẽ dụng cụ đã được phê duyệt, kết quả xác minh dụng cụ đáp ứng tất cả các yêu cầu, v.v. b). Các hồ sơ phát triển công cụ có thể bao gồm nhưng không giới hạn ở: bản vẽ dụng cụ, báo cáo xác minh dụng cụ, công cụ hồ sơ EC trong giai đoạn phát triển, mẫu, v.v. | E36: Score 0 - Do not meet requirement 1.1. Score 1 - Meet requirement 1.1. But do not meet requirement 1.2 and/or 1.3. Score 2 - Meet requirements 1.1, 1.2 and 1.3. But do not meet requirement 1.4. Score 3 - Meet all requirements. | F36: 3
A37: 2 | B37: Tooling Storage | C37: 2.1 Is there specified space to store the tooling? 2.2 Is there storage method proper to protect the tooling from damage and rusting? 2.3 Is the space sufficient to store all the tooling? | D37: 2.1 Có không gian cụ thể để lưu trữ dụng cụ không? 2.2 Có phương pháp lưu trữ thích hợp để bảo vệ dụng cụ khỏi bị hư hỏng và rỉ sét không? 2.3 Không gian có đủ để lưu trữ tất cả các dụng cụ không? | E37: Score 0 - Do not meet requirement 2.1 Score 1 - Meet requirement 2.1. But do not meet requirement 2.2. Score 2 - Meet requirement 2.1 and 2.2. But do not meet requirement 2.3. Score 3 - Meet all requirements. | F37: 3
A38: 3 | B38: Tooling Identification | C38: 3.1 Is there a tooling identification process in place? 3.2 Is the tooling identification information sufficient to avoid tooling mixture? 3.3 Is the tooling identification information easy to read? Notes: Tooling identification information may include but not limited to: tooling number, part number, revision, customer, etc. | D38: 3.1 Có quy trình nhận dạng dụng cụ tại chỗ không? 3.2 Thông tin nhận dạng dụng cụ có đủ để tránh hỗn hợp dụng cụ không? 3.3 Thông tin nhận dạng dụng cụ có dễ đọc không? Lưu ý: Thông tin nhận dạng dụng cụ có thể bao gồm nhưng không giới hạn ở: số dụng cụ, số bộ phận, sửa đổi, khách hàng, v.v. | E38: Score 0 - Do not meet requirement 3.1. Score 1 - Meet requirement 3.1. But do not meet requirement 3.2. Score 2 - Meet requirement 3.1 and 3.2. But do not meet requirement 3.3. Score 3 - Meet all requirements. | F38: 3
A39: 4 | B39: Tooling Preventive Maintenance | C39: 4.1 Are there tooling preventive maintenance schedule and tooling maintenance checklist in place? 4.2 Are all maintenance items defined in tooling maintenance checklist actually executed? 4.3 Are all tooling maintenance activities executed on time? | D39: 4.1 Có lịch trình bảo trì phòng ngừa dụng cụ và danh sách kiểm tra bảo trì dụng cụ tại chỗ không? 4.2 Tất cả các mục bảo trì được xác định trong danh sách kiểm tra bảo trì dụng cụ có thực sự được thực hiện không? 4.3 Có phải tất cả các hoạt động bảo trì dụng cụ được thực hiện đúng thời gian? | E39: Score 0 - Do not meet requirement 4.1. Score 1 - Meet requirement 4.1. But do not meet requirement 4.2. Score 2 - Meet requirement 4.1 and 4.2. But do not meet requirement 4.3. Score 3 - Meet all requirements. | F39: 3
A40: 5 | B40: Tooling Life Control | C40: 5.1 Is there a tooling life control process in place? 5.2 Are the design tooling life defined for all types of tooling? 5.3 Are the utilized life tracked for all tooling? 5.4 Are proper actions taken if tooling's utilizing life reach the design tooling life (i.e. build a replacement tooling and re-verify it, or get customer's approval to extending the tooling life)? Remark: Design tooling life = total utilizing times/cycles tooling can execute before tooling scrape. Utilized life = how many utilizing times/cycles tooling has actually executed. | D40: 5.1 Có quy trình kiểm soát tuổi thọ dụng cụ tại chỗ không? 5.2 Tuổi thọ dụng cụ thiết kế có được xác định cho tất cả các loại dụng cụ không? 5.3 Tuổi thọ sử dụng của dụng cụ có được theo dõi cho tất cả các dụng cụ không? 5.4 Các hành động phù hợp có được thực hiện nếu tuổi thọ sử dụng của dụng cụ đạt đến tuổi thọ của dụng cụ thiết kế (nghĩa là xây dựng một công cụ thay thế và xác minh lại hoặc chấp thuận của khách hàng để kéo dài tuổi thọ dụng cụ)? Ghi chú: Tuổi thọ dụng cụ thiết kế = tổng thời gian sử dụng / chu kỳ công cụ có thể thực hiện trước khi cạo dụng cụ.Cuộc sống được sử dụng = bao nhiêu lần sử dụng công cụ / chu kỳ thực sự đã thực hiện. | E40: Score 0 - Do not meet requirement 5.1. Score 1 - Meet requirement 5.1. But do not meet requirement 5.2 and/or 5.3. Score 2 - Meet requirements 5.1, 5.2 and 5.3. But do not meet requirement 5.4. Score 3 - Meet all requirements. | F40: 3
A41: 6 | B41: Tooling Spare Parts Control | C41: 6.1 Is there a tooling spare parts control process in place? 6.2 Are the minimum inventory set up for all necessary tooling spare parts? 6.3 Are the tooling spare parts' actual inventory monitored? 6.4 Have proper actions been taken when the tooling spare parts' actual inventory≤ minimum inventory. Notes: necessary tooling spare parts may include but not limited to: punches, die inserts, ejectors, pins, springs, screws, etc. | D41: 6.1 Có quy trình kiểm soát phụ tùng thay thế tại chỗ không? 6.2 Hàng tồn kho tối thiểu có được thiết lập cho tất cả các phụ tùng dụng cụ cần thiết không? 6.3 Hàng tồn kho phụ tùng dụng cụ có được theo dõi không? 6.4 Có hành động thích hợp được thực hiện khi hàng tồn kho tối thiểu của phụ tùng thay thế Lưu ý: phụ tùng dụng cụ cần thiết có thể bao gồm nhưng không giới hạn ở: đục lỗ, chèn chết, đầu phun, ghim, lò xo, ốc vít, v.v. | E41: Score 0 - Do not meet requirement 6.1. Score 1 - Meet requirement 6.1. But do not meet requirement 6.2 and/or 6.3. Score 2 - Meet requirement 6.1, 6.2 and 6.3. But do not meet requirement 6.4. Score 3 - Meet all requirements. | F41: 3
A42: 7 | B42: Tooling Change Management | C42: 7.1 Is there a tooling change management process defined? 7.2 Is the process followed in the actual tooling change activities? 7.3 Is tooling re-verification implemented after tooling change? 7.4 Is the tooling change information communicated to all related departments (i.e. tooling maintenance, production, engineering, quality, etc.) | D42: 7.1 Có quy trình quản lý thay đổi công cụ được xác định không? 7.2 Quá trình có tuân theo các hoạt động thay đổi dụng cụ thực tế không? 7.3 Xác minh lại công cụ có được thực hiện sau khi thay đổi công cụ không? 7.4 Thông tin thay đổi dụng cụ có được truyền đạt tới tất cả các bộ phận liên quan không (ví dụ: bảo trì dụng cụ, sản xuất, kỹ thuật, chất lượng, v.v.) | E42: Score 0 - Do not meet requirement 7.1. Score 1 - Meet requirement 7.1. But do not meet requirement 7.2 and/or 7.3. Score 2 - Meet requirement 7.1, 7.2 and 7.3. But do not meet requirement 7.4. Score 3 - Meet all requirements. | F42: 3
...
