Workbook
Name __CON1: #REF!
Name __CON2: #REF!
Name __NET2: #REF!
Name _1: #N/A
Name _2: #REF!
Name _3: #N/A
Name _4: #N/A
Name _CON1: #REF!
Name _CON2: #REF!
Name _DAT1: [1]Sheet1!#REF!
Name _DAT1: [2]Sheet1!#REF!
Name _DAT1: [1]Sheet1!#REF!
Name _DAT1: [1]Sheet1!#REF!
Name _DAT13: [1]Sheet1!#REF!
Name _DAT13: [2]Sheet1!#REF!
Name _DAT13: [1]Sheet1!#REF!
Name _DAT13: [1]Sheet1!#REF!
Name _DAT16: [1]Sheet1!#REF!
Name _DAT16: [2]Sheet1!#REF!
Name _DAT16: [1]Sheet1!#REF!
Name _DAT16: [1]Sheet1!#REF!
Name _DAT17: [1]Sheet1!#REF!
Name _DAT17: [2]Sheet1!#REF!
Name _DAT17: [1]Sheet1!#REF!
Name _DAT17: [1]Sheet1!#REF!
Name _DAT18: [1]Sheet1!#REF!
Name _DAT18: [2]Sheet1!#REF!
Name _DAT18: [1]Sheet1!#REF!
Name _DAT18: [1]Sheet1!#REF!
Name _DAT19: [1]Sheet1!#REF!
Name _DAT19: [2]Sheet1!#REF!
Name _DAT19: [1]Sheet1!#REF!
Name _DAT19: [1]Sheet1!#REF!
Name _DAT20: [1]Sheet1!#REF!
Name _DAT20: [2]Sheet1!#REF!
Name _DAT20: [1]Sheet1!#REF!
Name _DAT20: [1]Sheet1!#REF!
Name _DAT3: [1]Sheet1!#REF!
Name _DAT3: [2]Sheet1!#REF!
Name _DAT3: [1]Sheet1!#REF!
Name _DAT3: [1]Sheet1!#REF!
Name _DAT9: [1]Sheet1!#REF!
Name _DAT9: [2]Sheet1!#REF!
Name _DAT9: [1]Sheet1!#REF!
Name _DAT9: [1]Sheet1!#REF!
Name _NET2: #REF!
Name a277Print_Titles: #REF!
Name aerg: #N/A
Name Assessment_Types: #REF!
Name Assessment_Types: #REF!
Name B_Isc: #REF!
Name bang_gia: #REF!
Name BOQ: #REF!
Name BVCISUMMARY: #REF!
Name Calqty: #REF!
Name Calqty: #REF!
Name Choices: [5]Sheet7!$A$19:$A$20
Name Co: #REF!
Name code: #REF!
Name code: #REF!

Sheet Cover.
E13: Supplier name
E14: Major Product
E15: Audit Object
E16: Date of Audit
E17: Auditor
E18: Grade
E19: Result
B22: M&C Electronics Vina

Sheet Result Report
B1: Quality Process Audit Result Report
C3: □ Audit Result
C4: Audit Object | F4: =Cover.!G14 -> 0 | J4: Grade | M4: =Cover.!G18 -> 0 | O4: Date of Audit
C5: Major Product | F5: =Cover.!G15 -> 0 | J5: Auditor | M5: =Cover.!G17 -> 0 | O5: Auditee
C8: □Scores and Grade by sector
C9: No | D9: evaluation sector | E9: Evaluation requiment | H9: Evaluation result | M9: note
E10: the whole | H10: Result | K10: Degree of Completion
C11: 1 | D11: Warehouse for Materials | E11: =Checksheet!E59 -> 12 | H11: =Checksheet!G10 -> 0 | K11: =H11/E11*100 -> 0
C12: 2 | D12: Material Inspection and Preparation | E12: =Checksheet!E60 -> 16 | H12: =Checksheet!G16 -> 0 | K12: =H12/E12*100 -> 0
C13: 3 | D13: Control Tooling | E13: =Checksheet!E61 -> 21 | H13: =Checksheet!G23 -> 0 | K13: =H13/E13*100 -> 0
C14: 4 | D14: Production Process | E14: =Checksheet!E62 -> 18 | H14: =Checksheet!G33 -> 0 | K14: =H14/E14*100 -> 0
C15: 5 | D15: Product Evaluation (OQC) | E15: =Checksheet!E63 -> 18 | H15: =Checksheet!G42 -> 0 | K15: =H15/E15*100 -> 0
C16: 6 | D16: Packing and Shipment | E16: =Checksheet!E64 -> 15 | H16: =Checksheet!G51 -> 0 | K16: =H16/E16*100 -> 0
C17: Evaluation Score/Grade | E17: =SUM(H11:J16) -> 0 | H17: =IF(E17>=90,"A",IF(E17>=80,"B",IF(E17>=70,"C",IF(E17>=60,"D","E")))) -> E | K17: =IF(H17="A","Very Good",IF(H17="B"," Good",IF(H17="C","Need Improvement",IF(H17="D","Unsatisfactory","Unsatisfactory")))) -> Unsatisfactory
C19: □ Improvement object Status by type
C20: Classification | E20: Number of Cases
C21: Material Management
C22: Material Inspection and Preparation
C23: Production Process
C24: Product Evaluation
C25: Packing Management
C26: Total

Sheet Non-Conforming Item
B2: Quality Process Audit Non-Conforming Item
M5: 해결
M6: 미결
B8: Classification | C8: NO | D8: Problem | F8: Countermeasure for Improvement | J8: Confirmation Result | M8: Completion Status | N8: Reproducibility status
D9: Pointed-out Item | E9: Phenomenon | F9: Improvement Plan | G9: Picture | H9: Person in charge | I9: Schedule | J9: Confirmed content | K9: Schedule | L9: person in charge

Sheet Checksheet
C1: VENDOR QUALIFICATION CHECKSHEET | F1: Code of Form/ Mã số biểu mẫu | H1: PUR.04.00.05
F2: Effective Date/ Ngày hiệu lực | H2: 43503
C3: The first evaluation/ Đánh giá lần đầu | E3: The re-evaluation/ Đánh giá lại | F3: Page/ Tổng số trang | H3: 8
A4: Vendor code/ Mã vendor (ERP) | C4: Name of vendor/ Tên nhà cung cấp | E4: Address/ Địa chỉ | F4: Product type provide/ Loại sản phẩm cung cấp:
F5: Raw Material/ NVL chính o Sub material/ Phụ liệu | H5: Outsourcing Material/ NVL từ nguồn gia công
A6: P.I.C/ Người phụ trách | C6: Job title/ Chức vụ | D6: Department/ Phòng ban | E6: Email | F6: Phone No.
A9: CONTENT OF EVALUATION
A10: Section 1 - Warehouse for Materials | E10: Sub total (Score) | F10: =SUM(F13:F15) -> 12 | G10: =SUM(G13:G15) -> 0 | H10: COMMENT
E11: Achievement rate | F11: =F10/100 -> 0.12 | G11: =G10/100 -> 0
A12: Question Number | B12: Element | C12: Requirement | D12: VNM | E12: Rating Criteria | F12: Score | G12: Result
A13: 1 | B13: Standard | C13: Is the material storage standard established, and are the warehoused materials structuralized for first-in/first-out, and is there management tools? | D13: Tiêu chuẩn bảo quản vật liệu được thiết lập, có tiêu chuẩn first-in/first-out và có lịch sử quản lý không? | E13: Score 1: No standard for first-in/first-out, and materials in need of first-in/first-out are not managed. Score 2 : There is no management standard for first-in/first-out, but first-in/first-out is available for materias in need of it, or only the first-in/first-out management standard is retained. Score 3: There is first-in/first-out management standard, but required is partial improvement of the management object, or a state of management. Score 4 : The first-in/first-out management standard is established, and first-in, first-out process is in progress according to the management standard. | F13: 4
A14: 2 | B14: Environment | C14: Is the environmental condition of the warehouse under measurement control regularly? (temperature/humidity) | D14: Môi trường bảo quản thành phẩm có được quản lý không ( nhiệt độ, độ ẩm ) | E14: Score 1: : The environmental condition is not defined, nor is the temperature/humidity managed. Score 2: : Although the environmental condition is not defiend, temperature/humdity is managed, or the environmental condition for materials storage is established. Score 3: : The environmental condition is established, but a state of management needs to be improved. Score 4: : The environmental condition is established, and it is managed according to the established standard. | F14: 4
A15: 3 | B15: Layout | C15: Are the products classified by item in time of materials storage, and is there an identification mark for materials? | D15: Các nguyên vật liệu được phân loại theo mặt hàng trong thời gian lưu trữ , và có một dấu hiệu nhận dạng cho vật liệu không? | E15: Score 1: There is no standard for identification of the stored materials, and it's difficult to identify the materials in storage. Score 2 : Though there is no standard for identification of the materials in storage, the materials in storage are identified, or there is only the standard of identification management of the stored materials. Score 3: There is the identification standard of the materials in storage, but partial improvement is required. (difficulty in identifying some materials, etc.) Score 4: There is the identification standard of the materials in storage, and materials are identified according to the standard. | F15: 4
A16: Section 2- Material Inspection and Preparation | E16: Sub total (Score) | F16: =SUM(F19:F22) -> 16 | G16: =SUM(G19:G22) -> 0 | H16: COMMENT
E17: Achievement rate | F17: =15/100 -> 0.15 | G17: =G16/100 -> 0
A18: Question Number | B18: Element | C18: Question / Requirement | D18: VNM | E18: Rating Criteria | F18: Score | G18: Result
A19: 1 | B19: Material Inspection (WH) | C19: Are below critical quality control points of the material inspected in incoming? - Part Number and Lot Number - Maker/ Provider - Status of product - Packing condition - Quantity / Weight - Expiry Date | D19: Các điểm kiểm soát chất lượng quan trọng dưới đây của nguyên liệu có được đánh giá khi nhập vào? - Mã sản phẩm và số lot - Nhà sản xuất/ người cung ứng - Tình trạng của sản phẩm - Quy cách đóng gói - Số lượng / Trọng lượng - Ngày hết hạn | E19: Score 1 - More than 3 critical control point missed to be inspected in incoming. Score 2 - Some critical control points are inspected, but 2~3 critical control points missed. Score 3 - Some critical control points are inspected, but one critical control points missed. Score 4 - All critical control points are inspected in incoming | F19: 4
A20: 3 | B20: Material Inspection (IQC) | C20: Are below critical quality control points of material inspected ? - Spec - Appearance no damage, crack, broken, deform, …. | D20: Các điểm kiểm soát chất lượng quan trọng của vật liệu có được kiểm tra? - Quy cách kỹ thuật, chất lượng sản phẩm -Ngoại quan: Vết đâm,Crack,vỡ,Biến dạng, cong | E20: Score 1 - More than 3 critical control point missed to be inspected Score 2 - Some critical control points are inspected, but 2~3 critical control points missed. Score 3 - Some critical control points are inspected, but one critical control points missed. Score 4 - All critical control points are inspected | F20: 4
A21: 4 | B21: Material Inspection (IQC) | C21: - Does the supplier have a precision testing process and devices that measure the accuracy of the product? | D21: - Nhà cung cấp có quy trình kiểm tra độ chính xác và các thiết bị đo đạc độ chính xác của sản phẩm không? | E21: Score 1. Do not meet requirement 1.1. Score 2. Meet requirement 1.1. Only use of c. Score 3. Meet requirement 1.1. Use of a or b. Score 4. Meet all requirements. | F21: 4
A22: 5 | B22: Pot Life Control for Partially Used Material | C22: - Is there a pot life control process for partially used material, one times material ? - Is there expiration date/time of the partially used material marked? - Are all these partially used materials used before the expiration date/time? | D22: - Có quy trình kiểm soát thời hạn sử dụng nguyên vật liệu đối với loại được sử dụng một phần hoặc nhiều lần hay không? - Có ngày / thời gian hết hạn của vật liệu được sử dụng một phần được đánh dấu không? - Tất cả những vật liệu được sử dụng một phần này có được sử dụng trước ngày / thời gian hết hạn không? | E22: Score 1 - Do not meet requirement 4.1 Score 2 - Meet requirement 4.1, but found multiple cases do not meet requirement 4.2 and/or 4.3 and/or 4.4. Score 3- Meet requirement 4.1, but found isolated case do not meet requirement 4.2 and/or 4.3 and/or 4.4. Score 4- Meet all requirements | F22: 4
A23: Section 3- Control Tooling | E23: Sub total (Score) | F23: =SUM(F26:F32) -> 21 | G23: =SUM(G26:G29) -> 0 | H23: COMMENT
E24: Achievement rate | F24: =F23/100 -> 0.21 | G24: =G23/100 -> 0
A25: Question Number | B25: Element | C25: Question / Requirement | D25: VNM | E25: Rating Criteria | F25: Score | G25: Result
A26: 1 | B26: Tooling Release to Production | C26: 1.1 Is there a tooling release process in place? 1.2 Have all the tooling release requirements been met before the tooling release to production? 1.3 Is the tooling release document signed by authorized people before release to production? 1.4 Are the necessary tooling development records transferred to and maintained by tooling maintenance department. Notes: a). Tooling release requirements may include but not limited to: DFM has been approved by customer, tooling drawing has been approved, tooling verification result meet all requirements, etc. b). Tooling development records may include but not limited to: tooling drawing, tooling verification reports, tooling EC records in development stage, samples, etc. | D26: 1.1 Có quy trình phát hành dụng cụ tại chỗ không? 1.2 Tất cả các yêu cầu phát hành dụng cụ đã được đáp ứng trước khi phát hành dụng cụ vào sản xuất chưa? 1.3 Tài liệu phát hành dụng cụ có chữ ký của người được ủy quyền trước khi phát hành vào sản xuất không? 1.4 Các hồ sơ phát triển dụng cụ cần thiết được chuyển đến và duy trì bởi bộ phận bảo trì dụng cụ. Ghi chú: a). Yêu cầu phát hành dụng cụ có thể bao gồm nhưng không giới hạn ở: DFM đã được khách hàng chấp thuận, bản vẽ dụng cụ đã được phê duyệt, kết quả xác minh dụng cụ đáp ứng tất cả các yêu cầu, v.v. b). Các hồ sơ phát triển công cụ có thể bao gồm nhưng không giới hạn ở: bản vẽ dụng cụ, báo cáo xác minh dụng cụ, công cụ hồ sơ EC trong giai đoạn phát triển, mẫu, v.v. | E26: Score 0 - Do not meet requirement 1.1. Score 1 - Meet requirement 1.1. But do not meet requirement 1.2 and/or 1.3. Score 2 - Meet requirements 1.1, 1.2 and 1.3. But do not meet requirement 1.4. Score 3 - Meet all requirements. | F26: 3
A27: 2 | B27: Tooling Storage | C27: 2.1 Is there specified space to store the tooling? 2.2 Is there storage method proper to protect the tooling from damage and rusting? 2.3 Is the space sufficient to store all the tooling? | D27: 2.1 Có không gian cụ thể để lưu trữ dụng cụ không? 2.2 Có phương pháp lưu trữ thích hợp để bảo vệ dụng cụ khỏi bị hư hỏng và rỉ sét không? 2.3 Không gian có đủ để lưu trữ tất cả các dụng cụ không? | E27: Score 0 - Do not meet requirement 2.1 Score 1 - Meet requirement 2.1. But do not meet requirement 2.2. Score 2 - Meet requirement 2.1 and 2.2. But do not meet requirement 2.3. Score 3 - Meet all requirements. | F27: 3
A28: 3 | B28: Tooling Identification | C28: 3.1 Is there a tooling identification process in place? 3.2 Is the tooling identification information sufficient to avoid tooling mixture? 3.3 Is the tooling identification information easy to read? Notes: Tooling identification information may include but not limited to: tooling number, part number, revision, customer, etc. | D28: 3.1 Có quy trình nhận dạng dụng cụ tại chỗ không? 3.2 Thông tin nhận dạng dụng cụ có đủ để tránh hỗn hợp dụng cụ không? 3.3 Thông tin nhận dạng dụng cụ có dễ đọc không? Lưu ý: Thông tin nhận dạng dụng cụ có thể bao gồm nhưng không giới hạn ở: số dụng cụ, số bộ phận, sửa đổi, khách hàng, v.v. | E28: Score 0 - Do not meet requirement 3.1. Score 1 - Meet requirement 3.1. But do not meet requirement 3.2. Score 2 - Meet requirement 3.1 and 3.2. But do not meet requirement 3.3. Score 3 - Meet all requirements. | F28: 3
A29: 4 | B29: Tooling Preventive Maintenance | C29: 4.1 Are there tooling preventive maintenance schedule and tooling maintenance checklist in place? 4.2 Are all maintenance items defined in tooling maintenance checklist actually executed? 4.3 Are all tooling maintenance activities executed on time? | D29: 4.1 Có lịch trình bảo trì phòng ngừa dụng cụ và danh sách kiểm tra bảo trì dụng cụ tại chỗ không? 4.2 Tất cả các mục bảo trì được xác định trong danh sách kiểm tra bảo trì dụng cụ có thực sự được thực hiện không? 4.3 Có phải tất cả các hoạt động bảo trì dụng cụ được thực hiện đúng thời gian? | E29: Score 0 - Do not meet requirement 4.1. Score 1 - Meet requirement 4.1. But do not meet requirement 4.2. Score 2 - Meet requirement 4.1 and 4.2. But do not meet requirement 4.3. Score 3 - Meet all requirements. | F29: 3
A30: 5 | B30: Tooling Life Control | C30: 5.1 Is there a tooling life control process in place? 5.2 Are the design tooling life defined for all types of tooling? 5.3 Are the utilized life tracked for all tooling? 5.4 Are proper actions taken if tooling's utilizing life reach the design tooling life (i.e. build a replacement tooling and re-verify it, or get customer's approval to extending the tooling life)? Remark: Design tooling life = total utilizing times/cycles tooling can execute before tooling scrape. Utilized life = how many utilizing times/cycles tooling has actually executed. | D30: 5.1 Có quy trình kiểm soát tuổi thọ dụng cụ tại chỗ không? 5.2 Tuổi thọ dụng cụ thiết kế có được xác định cho tất cả các loại dụng cụ không? 5.3 Tuổi thọ sử dụng của dụng cụ có được theo dõi cho tất cả các dụng cụ không? 5.4 Các hành động phù hợp có được thực hiện nếu tuổi thọ sử dụng của dụng cụ đạt đến tuổi thọ của dụng cụ thiết kế (nghĩa là xây dựng một công cụ thay thế và xác minh lại hoặc chấp thuận của khách hàng để kéo dài tuổi thọ dụng cụ)? Ghi chú: Tuổi thọ dụng cụ thiết kế = tổng thời gian sử dụng / chu kỳ công cụ có thể thực hiện trước khi cạo dụng cụ.Cuộc sống được sử dụng = bao nhiêu lần sử dụng công cụ / chu kỳ thực sự đã thực hiện. | E30: Score 0 - Do not meet requirement 5.1. Score 1 - Meet requirement 5.1. But do not meet requirement 5.2 and/or 5.3. Score 2 - Meet requirements 5.1, 5.2 and 5.3. But do not meet requirement 5.4. Score 3 - Meet all requirements. | F30: 3
A31: 6 | B31: Tooling Spare Parts Control | C31: 6.1 Is there a tooling spare parts control process in place? 6.2 Are the minimum inventory set up for all necessary tooling spare parts? 6.3 Are the tooling spare parts' actual inventory monitored? 6.4 Have proper actions been taken when the tooling spare parts' actual inventory≤ minimum inventory. Notes: necessary tooling spare parts may include but not limited to: punches, die inserts, ejectors, pins, springs, screws, etc. | D31: 6.1 Có quy trình kiểm soát phụ tùng thay thế tại chỗ không? 6.2 Hàng tồn kho tối thiểu có được thiết lập cho tất cả các phụ tùng dụng cụ cần thiết không? 6.3 Hàng tồn kho phụ tùng dụng cụ có được theo dõi không? 6.4 Có hành động thích hợp được thực hiện khi hàng tồn kho tối thiểu của phụ tùng thay thế Lưu ý: phụ tùng dụng cụ cần thiết có thể bao gồm nhưng không giới hạn ở: đục lỗ, chèn chết, đầu phun, ghim, lò xo, ốc vít, v.v. | E31: Score 0 - Do not meet requirement 6.1. Score 1 - Meet requirement 6.1. But do not meet requirement 6.2 and/or 6.3. Score 2 - Meet requirement 6.1, 6.2 and 6.3. But do not meet requirement 6.4. Score 3 - Meet all requirements. | F31: 3
A32: 7 | B32: Tooling Change Management | C32: 7.1 Is there a tooling change management process defined? 7.2 Is the process followed in the actual tooling change activities? 7.3 Is tooling re-verification implemented after tooling change? 7.4 Is the tooling change information communicated to all related departments (i.e. tooling maintenance, production, engineering, quality, etc.) | D32: 7.1 Có quy trình quản lý thay đổi công cụ được xác định không? 7.2 Quá trình có tuân theo các hoạt động thay đổi dụng cụ thực tế không? 7.3 Xác minh lại công cụ có được thực hiện sau khi thay đổi công cụ không? 7.4 Thông tin thay đổi dụng cụ có được truyền đạt tới tất cả các bộ phận liên quan không (ví dụ: bảo trì dụng cụ, sản xuất, kỹ thuật, chất lượng, v.v.) | E32: Score 0 - Do not meet requirement 7.1. Score 1 - Meet requirement 7.1. But do not meet requirement 7.2 and/or 7.3. Score 2 - Meet requirement 7.1, 7.2 and 7.3. But do not meet requirement 7.4. Score 3 - Meet all requirements. | F32: 3
A33: Section 4- Production Process | E33: Sub total (Score) | F33: =SUM(F36:F41) -> 18 | G33: =SUM(G36:G41) -> 0 | H33: COMMENT
E34: Achievement rate | F34: =F33/100 -> 0.18 | G34: =G23/100 -> 0
A35: Question Number | B35: Element | C35: Question / Requirement | D35: VNM | E35: Rating Criteria | F35: Score | G35: Result
A36: 1 | B36: WI | C36: Manipulate and check yes according to the approval sheet standard and when the change has historical management and reflect changes to the approval sheet? Is the operation manual provided in the appropriate position for each machine and has standard operation? Is there a check sheet layout for each machine and daily recorded in the check sheet? | D36: Thao tác và kiểm tra có theo tiêu chuẩn approval sheet và khi thay đổi có quản lý lịch sử và phản ánh thay đổi vào approval sheet không? Bản hướng dẫn thao tác có được bố trí ở vị trí thích hợp theo từng máy không và có thao tác theo tiêu chuẩn hay không? Có bố trí check sheet theo từng máy và hàng ngày có ghi chép vào check sheet không? | E36: Score 0 - Do not meet requirement 1.1. Score 1 - Meet requirement 1.1. But do not meet requirement 1.2 and/or 1.3. Score 2 - Meet requirements 1.1, 1.2 and 1.3. But do not meet requirement 1.4. Score 3 - Meet all requirements. | F36: 3
A37: 2 | B37: CAM program | C37: Is there a standard of operating conditions (Cam)? - Feed, machining speed, number of turns, compliance with machining time, byte specification | D37: Có tuân thủ tiêu chuẩn điều kiện thao tác (Cam) không? - Feed, tốc độ gia công, số vòng, tuân thủ thời gian gia công, quy cách byte | E37: Score 0 - Do not meet requirement 2.1 Score 1 - Meet requirement 2.1. But do not meet requirement 2.2. Score 2 - Meet requirement 2.1 and 2.2. But do not meet requirement 2.3. Score 3 - Meet all requirements. | F37: 3
A38: 3 | B38: Washing | C38: After the processing, do you perform the washing? | D38: Sau khi gia công có tiến hành công đoạn rửa không? | E38: Score 0 - Do not meet requirement 3.1. Score 1 - Meet requirement 3.1. But do not meet requirement 3.2. Score 2 - Meet requirement 3.1 and 3.2. But do not meet requirement 3.3. Score 3 - Meet all requirements. | F38: 3
A39: 4 | B39: Oil | C39: Using cutting oil suitable for machining purposes? Is there any standard for oil concentration management? | D39: Sử dụng dầu cắt gọt phù hợp với mục đích gia công hay không? Có tiêu chuẩn quản lý nồng độ dầu không? | E39: Score 0 - Do not meet requirement 4.1. Score 1 - Meet requirement 4.1. But do not meet requirement 4.2. Score 2 - Meet requirement 4.1 and 4.2. But do not meet requirement 4.3. Score 3 - Meet all requirements. | F39: 3
A40: 5 | B40: Sample | C40: Is the standard form approved and arranged in line? Is there any specific area for the row before input and after the input | D40: Mẫu tiêu chuẩn được phê duyệt và có bố trí ở line hay không? Có phận biệt khu vực để hàng trước input và sau input không | E40: Score 0 - Do not meet requirement 5.1. Score 1 - Meet requirement 5.1. But do not meet requirement 5.2 and/or 5.3. Score 2 - Meet requirements 5.1, 5.2 and 5.3. But do not meet requirement 5.4. Score 3 - Meet all requirements. | F40: 3
A41: 6 | B41: Quality process | C41: Will FML management follow the established criteria? - Confirm the test date and sample state - confirm whether the original sample product is preserved within 3 months (date, time, mold number, record the number of samples to sample) - After Tapping and hole do you manage the inside diameter of the hole? - Make sure there are separate locations for measuring and preserving samples | D41: Quản lý FML có tiến hành theo tiêu chuẩn đã định ra không? - Xác nhận ngày kiểm tra và trạng thái sample - xác nhận sản phẩm mẫu ban đầu có được bảo bảo quản trong vòng 3 tháng hay không ( ngày tháng , thời gian, số khuôn, ghi chép số máy về sample) - Sau khi Tapping và làm hole có quản lý kích thước đường kính trong của hole không? - Đảm bảo có địa điểm riêng để đo và bảo quản sample | E41: Score 0 - Do not meet requirement 6.1. Score 1 - Meet requirement 6.1. But do not meet requirement 6.2 and/or 6.3. Score 2 - Meet requirement 6.1, 6.2 and 6.3. But do not meet requirement 6.4. Score 3 - Meet all requirements. | F41: 3
A42: Section 5- Product Evaluation (OQC) | E42: Sub total (Score) | F42: =SUM(F35:F41) -> 18 | G42: =SUM(G35:G41) -> 0 | H42: COMMENT
...
