Workbook
Name __DemandLoad: TRUE
Name _1: #N/A
Name _1_?: #REF!
Name _1_?: #REF!
Name _2PBook_Area: #REF!
Name _2PBook_Area: #REF!
Name A: "?A*"
Name AA: #REF!
Name aaa: #REF!
Name ALTSS: #REF!
Name AS: #REF!
Name AS.BB: #REF!
Name AZ: #REF!
Name b23RTDKDK: #REF!
Name Blatt1: #REF!
Name Blatt11: #REF!
Name Blatt12: #REF!
Name Blatt13: #REF!
Name Blatt3: #REF!
Name bRTDKDK: #REF!
Name data: #REF!
Name dd: #REF!
Name ED3__회훈_71.4_신창_4.9: #REF!
Name EO관리신: #REF!
Name FC_00: 0
Name FC_01: 70700
Name FC_02: 74700
Name FC_03: 76300
Name FC_04: 77700
Name FC_05: 78200
Name FC_06: 78300
Name FC_07: 3900+79200
Name FC_99: 0
Name FDFS: #REF!
Name FF: #REF!
Name fg: #REF!
Name FG24RTDKDK: #REF!
Name FGR12C15TBTB1RTDKDK: #REF!
Name fgTBTB3RTDKDK: #REF!
Name fgTBTB4RTDKDK: #REF!
Name FO_00: 56900
Name FO_01: 60800
Name FO_02: 68700
Name FO_03: 70200
Name FO_04: 69200
Name FO_05: 36300
Name FO_06: 0
Name FO_07: 0
Name FO_99: 23700
Name Folgeseiten: #REF!
Name G: #REF!
Name GH: #REF!
Name H11A01K: #REF!
Name HH: #REF!
Name II: #REF!
Name JJ: #REF!
Name K: #REF!
Name KK: #REF!
Name LC_00: 281000
Name LC_01: 258000

Sheet 1. History cover
B2: Quality Process Audit Công ty M&C Electronics Vina
B5: NO | C5: Ngày sửa đổi | D5: Mã số tài liệu | E5: Version | F5: Nội dung sửa đổi | G5: Lập | H5: Kiểm tra | I5: Duyệt
B6: 0 | C6: 2014.06.07 | D6: QM.04.00.21 | E6: 0 | F6: Lập mới Release | G6: Nguyễn Văn Lực | H6: Kim Byoung Kwan | I6: Joung Ui Young
B7: 1 | C7: 2023.06.02 | D7: QM.04.00.21 | E7: 1 | F7: Bổ sung thêm mục check PMEA và CP theo yêu cầu IATF16949 và mục check theo yêu cầu của khách hàng Hosiden trong mục số 12 (Đảm bảo sản xuất) Additional check item PMEA and CP as required by IATF16949 and check item at Hosiden customer's request in item 10 (Production Guarantee) | G7: N.T.Trang Nhung | H7: Nguyễn Tuấn Vũ | I7: Kim Byoung Kwan
B8: 2 | C8: 2024.04.04 | D8: QM.04.00.21 | E8: 2 | F8: Sửa đổi các mục trong check sheet theo các công đoạn thực tế M&C Modify the items in the check sheet according to the actual M&C process | G8: N.T.Trang Nhung | H8: Koh Jin Suk | I8: Park Seong Oh

Sheet 2.배점분포
B2: Checksheet for Quality Process Audit | M2: QM 04.00.21/Rev02
B3: 1. 기본사항/ information basic
B4: 협력회사명 Company name | E4: M&C Electronics | H4: Audit 부서 | J4: QA team | L4: 평가일자&Shift Audit date& Shift | M4: 05-04-2024/ Day Shift
B5: 피평가자(수검자명)/ Auditee/ Đối tượng | E5: Process | H5: Auditor | J5: Mrs.Nhung | L5: 등급 Rank/ Xếp loại | M5: A
B6: Tỉ lệ điểm (Rate) | E6: =L23 -> 0
B8: 2. 평가결과/ Evaluation result
B9: No | C9: 평가 항목 Evaluation items Hạng mục đánh giá | H9: 배점 Point Điểm | J9: 득점 Score Điểm đạt được | L9: 100점 환산 점수(%) Tỉ lệ đạt được
B10: 1 | C10: 1. 공통/일반 Quản lý Chung | H10: =SUM('3. Check sheet audit'!$E$4:$E$12) -> 25 | J10: =SUM('3. Check sheet audit'!$F$4:$F$12) -> 0 | L10: =J10/H10 -> 0
B11: 2 | C11: 2. 수입검사 및원자재 보관 Bảo quản nguyên vật liệu và kiểm tra đầu vào | H11: =SUM('3. Check sheet audit'!E13:E22) -> 26 | J11: =SUM('3. Check sheet audit'!F13:F22) -> 0 | L11: =J11/H11 -> 0
B12: 3 | C12: 3. 사출공정 Công đoạn injection | H12: =SUM('3. Check sheet audit'!E23:E35) -> 36 | J12: =SUM('3. Check sheet audit'!F23:F35) -> 0 | L12: =J12/H12 -> 0
B13: 4 | C13: 4. 용해 공정및용탕성분 분석Công đoạn lò nung và phân tích nóng chảy | H13: =SUM('3. Check sheet audit'!E36:E45) -> 28 | J13: =SUM('3. Check sheet audit'!F36:F45) -> 0 | L13: =J13/H13 -> 0
B14: 5 | C14: 5. 다이캐스팅 Die casting | H14: =SUM('3. Check sheet audit'!E46:E54) -> 24 | J14: =SUM('3. Check sheet audit'!F46:F54) -> 0 | L14: =J14/H14 -> 0
B15: 6 | C15: 6. 트리밍 및 샷 블래스터 Triming và shot blaster | H15: =SUM('3. Check sheet audit'!E55:E67) -> 32 | J15: =SUM('3. Check sheet audit'!F55:F67) -> 0 | L15: =J15/H15 -> 0
B16: 7 | C16: 7. 연마 및 핫프레스 Polishing &Hot Press | H16: =SUM('3. Check sheet audit'!E68:E74) -> 19 | J16: =SUM('3. Check sheet audit'!F68:F74) -> 0 | L16: =J16/H16 -> 0
B17: 8 | C17: 8. 배럴 및 크로메이트 Barrel & Chromate | H17: =SUM('3. Check sheet audit'!E75:E85) -> 32 | J17: =SUM('3. Check sheet audit'!F75:F85) -> 0 | L17: =J17/H17 -> 0
B18: 9 | C18: 9. 가공 Gia công CNC | H18: =SUM('3. Check sheet audit'!E86:E103) -> 45 | J18: =SUM('3. Check sheet audit'!F86:F103) -> 0 | L18: =J18/H18 -> 0
B19: 10 | C19: 10. 세척 Cleaning | H19: =SUM('3. Check sheet audit'!E104:E108) -> 15 | J19: =SUM('3. Check sheet audit'!F104:F108) -> 0 | L19: =J19/H19 -> 0
B20: 11 | C20: 11. 인쇄 및 레이저 및 조립 Print & Laser & Assy | H20: =SUM('3. Check sheet audit'!E109:E125) -> 38 | J20: =SUM('3. Check sheet audit'!F109:F125) -> 0 | L20: =J20/H20 -> 0
B21: 12 | C21: 12. 비파괴및파괴 검사 Kiểm tra công đoạn và leak test | H21: =SUM('3. Check sheet audit'!E126:E135) -> 27 | J21: =SUM('3. Check sheet audit'!F126:F135) -> 0 | L21: =J21/H21 -> 0
B22: 13 | C22: 13. 검사및출하 공정Kiểm tra và xuất hàng | H22: =SUM('3. Check sheet audit'!E136:E145) -> 29 | J22: =SUM('3. Check sheet audit'!F136:F145) -> 0 | L22: =J22/H22 -> 0
B23: Total | H23: =SUM(H10:H22) -> 376 | I23: =SUM(I10:I22) -> 0 | J23: =SUM(J10:J22) -> 0 | K23: =SUM(K10:K22) -> 0 | L23: =J23/H23 -> 0
B26: 3. Audit 평가 등급 Evaluation result
B27: 배점기준 Tiêu chuẩn phân bổ điểm | D27: 충분히 진행하고 증거가 있다/Có thực hiện & đủ bằng chứng: 4/3/2
D28: 실행은 있지만 불충분한다/ Không đầy đủ & 없음/ Không có: 0
B30: No | C30: Rank/ Xếp loại | D30: Score/ Số điểm | E30: Chi tiết/ Detail
B31: 1 | C31: □ A - Tốt Good | D31: > 90 | E31: Pass/Đạt
B32: 2 | C32: □ B - Khá Quite Well | D32: 80~90
B33: 3 | C33: □ C - Trung bình/ Not good | D33: 65~79 | E33: Fail/ Cần cải tiến và đánh giá lại sau cải tiến
B34: 4 | C34: □ D - Yếu Bad | D34: ＜65

Sheet 3. Check sheet audit
B2: QUALITY PROCESS AUDIT CHECK SHEET | E2: QM 04.00.21/Rev02
B3: Process | C3: Question no. | D3: 관리항목 or Spec Hạng mục quản lý và Spec | E3: Standard score | F3: 결과(점수) Kết quả ( Số điểm) | G3: Comments
B4: 1. 공통 Chung | C4: 1.1 | D4: 바코드 적용 시 불량 방지 E/P 적용 유무 Có áp dụng E/P ngăn ngừa lỗi khi áp dụng check bar code không | E4: 3
C5: 1.4 | D5: 낙하품 처리 절차 수립 및 이력 관리 여부 Có lịch sử quản lý và thiết lập trình tự xử lý hàng bị rơi không | E5: 2
C6: 1.5 | D6: Có quản lý tỷ lệ lỗi công đoạn & monitoring không? 공정 불량율은 관리도로 작성하여 Monitoring되고 있는가? | E6: 3
C7: 1.6 | D7: 업무 목표를 잘 관리하기 위해 KPI를 설정한것 있습니까 ? Có căn cứ thiết lập KPI và quản lý tốt mục tiêu công việc không? | E7: 4
C8: 1.7 | D8: Có thực hiện đào tạo nội bộ và kế hoạch nâng cao năng lực không? 내부 교육 및 능력 강화 계획 있습니까 ? | E8: 2
C9: 1.8 | D9: 직무별 역량인증 관리 및 인증서류 발급이 있다 Có quản lý chứng nhận năng lực và hồ sơ cấp chứng nhận cho từng vị trí làm việc | E9: 2
C10: 1.9 | D10: 프로세스 위험 분석(예: PFMEA), 관리 계획 및 관련 문서의 효과적인 구현 감사 Có kiểm tra việc thực hiện hiệu quả phân tích rủi ro quy trình (chẳng hạn như PFMEA), kế hoạch kiểm soát và các tài liệu liên quan | E10: 4
C11: 1.10 | D11: 바코드 각인 및 스캔 진행으로 추적성 확보 (도면 반영 시 필수 사항) * LGIT와 동일사양, 동일조건 스캔 권장 * 바코드 리딩 테스트 기준설정 근거확보 * 등급 판정 유효성 및 기록관리 필수 Đảm bảo tính truy tìm nguồn gốc qua scan và khắc bar code ( hạng mục cần phản ánh ở bản vẽ) * Khuyến nghị scan cùng thông số kỹ thuật như LGIT, cùng điều kiện scan * Cần show căn cứ thiết lập tiêu chuẩn TEST đọc bar code * Cần quản lý ghi chép và tính hiệu quả đánh giá cấp bậc ( Level ) | E11: 3
C12: 1.11 | D12: 설비 재가동 프로세스 수립 여부 (휴지 시간,폐기 수량,조치 사항 등) Có thiết lập process cho máy móc hoạt động lại không ( thời gian nghỉ, số lượng phế, hạng mục xử lý,.. | E12: 2
B13: 2. 수입검사 및 원자재 보관 Bảo quản nguyên vật liệu và kiểm tra đầu vào | C13: 2.1 | D13: 원자재 외관 검사 기준 정합성 및 이행 상태 검사 기준 필수 포함 항목 : 기포, 수축, 오염, 이물, 부식 등 없을것 파단면 검사 (한도견본 활용 검사) 이행 여부 예) 기포 Size = 가로x세로 20mm내에 Ø3mm 이하 Tính phù hợp tiêu chuẩn kiểm tra ngoại quan nguyên vật liệu và hiện trạng thực hiện Hạng mục bao gồm tiêu chuẩn kiểm tra bắt buộc: không có rỗ khí, lồi lõm, bẩn, dị vật, han ghỉ ... Có thực hiện kiểm tra mặt cắt hay không ( sử dụng mẫu hạn độ kiểm tra ) ※ Kích thước rỗ khí= dài X rộng trong khoảng 20mm, Ø dưới 3mm | E13: 3
C14: 2.2 | D14: 원자재 성분 검사 이행 상태 (Cu, Si, Mg, Zn, Fe, Mn, Ni, Sn, Al 함유량 확인) ※ HKMC 기준 MS-SPEC 만족할 것 (AL 합금 종류별) 타 고객사의 경우 고객 요구 사항에 만족할 것 Hiện trạng thực hiện kiểm tra thành phần nguyên vật liệu ( xác nhận hàm lượng Cu, Si, Mg, Zn, Fe, Mn, Ni, Sn, Al) ※ MS-SPEC thỏa mãn tiêu chuẩn HKMC (theo từng chủng loại hợp kim AL) Trường hợp là công ty khác thì phải thỏa mãn yêu cầu của khách hàng | E14: 3
C15: 2.3 | D15: 원자재 중금속 유해물질 검사 (MS201-2 만족할 것) ※ M/SHEET 성분 측정값 비교 검증 Kiểm tra nguyên vật liệu chất độc hại kim loại nặng ( thỏa mãn MS201-2) ※ Kiểm chứng so sánh giá trị đo thành phần M/SHEET | E15: 3
C16: 2.4 | D16: 성분 중요항목 업체 VS 수입검사 편차관리 실시 中 (SI, FE, CU ) --> 절삭성, 주조성, 파단력 영향 --> 초기 편차관리 Spec 근거 확보 Tiến hành quản lý sự chênh lệch kiểm tra đầu vào VS thành phần chính Vendor (SI, FE, CU ) --> Ảnh hưởng của khả năng gia công, khả năng đúc và lực phá hủy ( kéo đứt) --> Đảm bảo Spec quản lý chênh lệch ban đầu | E16: 2
C17: 2.5 | D17: 입고품 검사 전/후 합부판정 식별 TAG부착(혼입방지) Dán TAG phân biệt hàng đạt/ không đạt và hàng nhập kho trước/ sau kiểm tra ( tránh lẫn hàng) | E17: 3
C18: 2.6 | D18: 입고품 원소재별 / 업체별 구분 적재 Phân loại, sắp xếp hàng nhập kho theo từng nguyên vật liệu/ theo từng vendor | E18: 2
C19: 2.7 | D19: 원자재 재고 현황판 비치 (안전재고 설정) Bố trí bảng hiện trạng tồn kho nguyên vật liệu ( thiết lập tồn kho an toàn) | E19: 2
C20: 2.8 | D20: 원자재 선입선출 운영 Vận hành nhập trước xuất trước nguyên vật liệu | E20: 3
C21: 2.9 | D21: 원자재 부적합품 식별격리, 반송 및 이력관리 Quản lý cách ly phân biệt nguyên vật liệu NG, gửi trả lại và quản lý lịch sử | E21: 3
C22: 2.10 | D22: 원자재 보관 및 수입 검사 장소 3정5S 활동 Thực hiện 3D5S địa điểm bảo quản nguyên vật liệu và nơi kiểm tra đầu vào | E22: 2
B23: 3. Công đoạn injection 사출공정 | C23: 3.1 | D23: Có tiêu chuẩn quản lý Resin (bao gồm bảo quản)? Có tuân thủ tiêu chuẩn? RESIN 에 대한 관리기준(보관 포함)은 설정되어 있으며 기준은 준수 되고 있는가? | E23: 3
C24: 3.2 | D24: Có quản lý thời gian sấy & nhiệt độ của Resin? RESIN의 건조시간 및 온도는 관리가 되고 있는가? | E24: 2
C25: 3.4 | D25: Vendor Injection/số máy injection có giống với nội dung trong approval sheet? (cùng Vendor/cùng maker/xác nhận số TON cùng injection) 사출업체/사출호기가 승인원 기재된 내용과 일치하는가?(동일회사內/ 동일MAKER /동일사출 TON수 인정) | E25: 2
C26: 3.5 | D26: Giá trị setting máy injection và bảng điều kiện định hình được approval có giống & nằm trong dung sai ±10%? (miệng phun/nhiệt độ xi-lanh : ±10%, tốc độ/áp lực : 5%, ngoài ra là ±10%) 승인 성형 조건표와 사출기 Setting값은 ±10% 이내로 일치하는가?(노즐/실린더온도: ±10℃, 속도/압력:5%, 그외±10% 이내) | E26: 3
C27: 3.6 | D27: Bảng điều kiện định hình & đánh giá thiết bị có được bố trí? Có quản lý lý lịch thay đổi? 성형조건표 및 설비점검표는 비치되어 있으며 변경이력은 관리하는가? | E27: 3
C28: 3.7 | D28: Nhiệt độ miệng phun xilanh có quản lý phân bố? 실린더 노즐온도는 산포 관리가 되고 있는가? | E28: 4
C29: 3.8 | D29: Nhiệt độ Hot runner có quản lý phân bố? HOT RUNNER 온도는 산포 관리 되고 있는가? | E29: 4
C30: 3.9 | D30: Có quản lý lý lịch các khuôn? (số Shot, nội dung sửa, nội dung PM, di chuyển khuôn) 각 금형의 이력관리는 되고 있는가? (SHOT수, 수정/수리내역, PM내용, 금형이동 사항) | E30: 3
C31: 3.10 | D31: Có quản lý phân loại hiển thị các loại khuôn sản xuất/A.S/hủy? 양산/ A.S / 폐기 금형별로 구분 식별 관리 되고 있는가? | E31: 2
C32: 3.11 | D32: Trạng thái bảo quản khuôn đang sử dụng có tốt? - phương pháp chồng xếp, ngăn bui thâm nhập, xử lý chống gỉ 사용중인 금형보관상태는 양호한가? - 적재방법, 이물유입방지, 방청처리 | E32: 2
C33: 3.12 | D33: Việc kiểm tra sản phẩm sản xuất trong công đoạn có được vận hành theo tiêu chuẩn quản lý nội bộ? 공정 생산품 검사는 내부 관리 기준대로 운영되는가? | E33: 3
C34: 3.13 | D34: Khi làm thao tác cắt gọt có chú ý thao tác để ngăn không bị dính bụi, dầu không? 사상작업시 취급부주의에 의한 이물, 유분 유착이 방지되도록 작업되고 있는가? | E34: 2
C35: 3.14 | D35: Thao tác cắt Gate có được tiến hành theo phương pháp có thể giảm tối đa sự phân bố? Gate 사상 작업은 산포를 최소화 할수 있는 방법으로 작업하고 있는가? | E35: 3
B36: 4. 용해 공정 및 용탕 성분 분석 Công đoạn lò nung và phân tích thành phần nóng chảy | C36: 4.1 | D36: 혼합 용해에 대한 작업 기준 수립 여부(※ 기준설정 근거확보) 예) 신재 (6) / 스크랩 (4) 주기적인 실측관리 실시 여부 Có thành lập tiêu chuẩn thao tác về lò lung hỗn hợp không VD: nguyên vật liệu mới (6)/ scrap(4) Có tiến hành quản lý hiệu suất định kỳ không | E36: 3
C37: 4.2 | D37: 탈가스 처리 질소/교반시간 기준 수립 여부 예) 최소 10분 이상 Có thành lập tiêu chuẩn Nito / thời gian khuấy xử lý Degassing- sục khí gas hay không VD: ít nhất trên 10p | E37: 3
C38: 4.3 | D38: 드로스 처리제 투입량 기준 수립 여부 (※ 기준설정 근거확보) 예) 용탕 1,000Kg당 1~2kg Có thành lập tiêu chuẩn lượng input FLUX xử lý cặn hay không ( ※ Cần show căn cứ dựa vào đâu để thiết lập tiêu chuẩn) VD: Mỗi 1000Kg nóng chảy là 1~2kg | E38: 3
C39: 4.4 | D39: 진정 시간 기준 수립 여부 예) 최소 20분 이상 (질소처리 시간 포함) Tiêu chuẩn thời gian ổn định lò có được thiết lập không VD: Tối thiểu trên 20 phút (bao gồm cả thời gian xử lý Nito) | E39: 3
C40: 4.5 | D40: 용해 온도 및 출탕 온도 기준 수립 여부 (※ 기준설정 근거확보) 예) ALDC 12종 기준 : 용해 온도 700±20℃ CÓ thành lập tiêu chuẩn nhiệt độ lò nung và tiêu chuẩn nhiệt độ kim loại nóng chảy khi múc ra khỏi lò hay không ( ※ Cần show căn cứ dựa vào đâu để thiết lập tiêu chuẩn) VD) Tiêu chuẩn ALDC 12: Nhiệt độ lò nung 700±20℃ | E40: 3
C41: 4.6 | D41: 용해로 및 작동유 온도 등 주기적 실측비교 So sánh giá trị đo định kỳ của lò nung và nhiệt độ dầu thủy lực v.v. | E41: 2
...

Sheet 4. OIL
B1: Correction action
B2: No. Stt | C2: Question No. Số câu hỏi | D2: Audit findings Lỗi phát hiện | E2: Evidence (before) | F2: Corrective actions Đối sách cải tiến | G2: Evidence (after) | H2: Responsibility PIC chịu trách nhiệm | I2: Audit date ngày audit | J2: Completion date Ngày hoàn thiện cải tiến | K2: Status Tình trạng | L2: Effectiveness Đánh giá hiệu quả | M2: Check for improvements again date Ngày kiểm tra lại cải tiến
