Workbook

Sheet Summary
A1: FDA _ MAUDE SUMMARY
A3: No. | B3: Model Number | C3: Device Problem | D3: Event Date | E3: Event Description | F3: Cause | G3: Affect by our process
A4: 1 | B4: 9438-06 | C4: Wireless Communication Problem | D4: 43897 | E4: It was reported that signal loss over one hour occurred. No product or data was provided for evaluation. Confirmation of the allegation and a probable cause could not be determined. No injury or medical intervention was reported. | F4: The signal loss was related to the mobile application => Could not determined the cause | G4: No
A5: 2 | B5: 9445-02 | C5: Wireless Communication Problem | D5: 43899 | E5: It was reported that signal loss over one hour occurred. A review of the share logs was performed and signal loss was found within the investigation window. The allegation was confirmed. The probable cause could not be determined. No injury or medical intervention was reported. | F5: The signal loss was related to the mobile application => Could not determined the cause | G5: No
A6: 3 | B6: 9445-02 | C6: Wireless Communication Problem | D6: 43897 | E6: It was reported that signal loss over one hour occurred. A review of the share logs was performed and signal loss was found within the investigation window. The allegation was confirmed. The probable cause was the transmitter and app were unable to establish a connection. No injury or medical intervention was reported. | F6: The signal loss was related to the mobile application => Due to Transmitter and app were unable establish a connection | G6: No
A7: 4 | B7: 9445-02 | C7: Wireless Communication Problem | D7: 43883 | E7: It was reported that signal loss over one hour occurred. A review of the share logs was performed and signal loss was found within the investigation window. The allegation was confirmed. The probable cause was the patient closed the mobile app. No injury or medical intervention was reported. | F7: The signal loss was related to the mobile application => Due to patient closed the mobile app | G7: No
A8: 5 | B8: MT24078 | C8: Wireless Communication Problem | D8: 43899 | E8: It was reported that signal loss over one hour occurred. No product or data was provided for evaluation. Confirmation of the allegation and a probable cause could not be determined. No injury or medical intervention was reported. | F8: The signal loss was related to the mobile application => Could not determined the cause | G8: No
A9: 6 | B9: 9438-06 | C9: Wireless Communication Problem | D9: 43897 | E9: It was reported that signal loss over one hour occurred. No product or data was provided for evaluation. Confirmation of the allegation and a probable cause could not be determined. No injury or medical intervention was reported. | F9: The signal loss was related to the mobile application => Could not determined the cause | G9: No
A10: 7 | B10: 9445-02 | C10: Wireless Communication Problem | D10: 43894 | E10: It was reported that signal loss over one hour occurred. No product or data was provided for evaluation. Confirmation of the allegation and a probable cause could not be determined. No injury or medical intervention was reported. | F10: The signal loss was related to the mobile application => Could not determined the cause | G10: No
A11: 8 | B11: 9438-06 | C11: Wireless Communication Problem | D11: 43899 | E11: It was reported that a loss of connection occurred. A review of the share logs was performed and a loss of connection was found within the investigation window. the allegation was confirmed. The probable cause could not be determined. No injury or medical intervention was reported. | F11: Loss of connection was related to the mobile application => Could not determined the cause | G11: No
A12: 9 | B12: 9445-02 | C12: Wireless Communication Problem | D12: 43908 | E12: It was reported that signal loss over one hour occurred. A review of the share logs was performed and signal loss was found within the investigation window. The allegation was confirmed. The probable cause could not be determined. No injury or medical intervention was reported. | F12: The signal loss was related to the mobile application => Could not determined the cause | G12: No
A13: 10 | B13: 9500-45 | C13: Break | D13: 43902 | E13: It was reported that a broken sensor wire occurred. The sensor was inserted at the abdomen on (b)(6) 2020. No product was provided for evaluation. Confirmation of the allegation and probable cause could not be determined. No injury or medical intervention was reported. | F13: Sensor wire broken => Could not determined the cause | G13: No
A14: 11 | B14: 9445-02 | C14: Wireless Communication Problem | D14: 43908 | E14: It was reported that signal loss over one hour occurred. No product or data was provided for evaluation. Confirmation of the allegation and a probable cause could not be determined. No injury or medical intervention was reported. | F14: The signal loss was related to the mobile application => Could not determined the cause | G14: No
A15: 12 | B15: 9445-02 | C15: Wireless Communication Problem | D15: 43885 | E15: It was reported that signal loss over one hour occurred. Data was provided for evaluation. Per (b)(4), cases where the sensor session line is missing in share support tool and share support service, complaints will be closed since a data investigation cannot be completed as data ambiguity cannot be resolved further. The allegation was undetermined. The probable cause could not be determined. No injury or medical intervention was reported. | F15: The signal loss was related to the mobile application => Could not determined the cause | G15: No
... A32: 29 | B32: 9445-02 | C32: Wireless Communication Problem | D32: 43909 | E32: It was reported that signal loss over one hour occurred. A review of the share logs was performed and signal loss was found within the investigation window. The allegation was confirmed. The probable cause could not be determined. No injury or medical intervention was reported. | F32: The signal loss was related to the mobile application => Could not determined the cause | G32: No
A33: 30 | B33: 9445-02 | C33: Wireless Communication Problem | D33: 02-29-20 | E33: It was reported that signal loss over one hour occurred. No product or data was provided for evaluation. Confirmation of the allegation and a probable cause could not be determined. No injury or medical intervention was reported. | F33: The signal loss was related to the mobile application => Could not determined the cause | G33: No
A34: 31 | B34: 9445-02 | C34: No Device Output | D34: 03/15/2020 | E34: It was reported that a transmitter failed error occurred. Data was evaluated and the allegation was confirmed. The probable cause could not be determined. No injury or medical intervention was reported. | F34: Transmitter failed error => Could not determined the cause | G34: No
A35: 32 | B35: 9445-02 | C35: Wireless Communication Problem | D35: 44138 | E35: It was reported that signal loss over one hour occurred. Data was provided for evaluation. Per doc (b)(4), cases where the sensor session line is missing in share support tool and share support service, complaints will be closed since a data investigation cannot be completed as data ambiguity cannot be resolved further. The allegation was undetermined. The probable cause could not be determined. No injury or medical intervention was reported. | F35: The signal loss was related to the mobile application => Could not determined the cause | G35: No
A36: 33 | B36: 9445-02 | C36: Wireless Communication Problem | D36: 44107 | E36: It was reported that signal loss over one hour occurred. A review of the share logs was performed and signal loss was found within the investigation window. The allegation was confirmed. The probable cause could not be determined. No injury or medical intervention was reported. | F36: The signal loss was related to the mobile application => Could not determined the cause | G36: No
A37: 34 | B37: 9445-02 | C37: No Device Output | D37: 43905 | E37: It was reported that transmitter failed error occurred. Data was evaluated and the allegation was confirmed. The probable cause was determined to be a low transmitter battery. No injury or medical intervention was reported | F37: Transmitter failed error => Due to battery of Transmitter was low | G37: No
A38: 35 | B38: MT22949 | C38: Wireless Communication Problem | D38: 43901 | E38: It was reported that signal loss over one hour occurred. No product or data was provided for evaluation. Confirmation of the allegation and a probable cause could not be determined. No injury or medical intervention was reported | F38: The signal loss was related to the mobile application => Could not determined the cause | G38: No
A39: 36 | B39: 9445-02 | C39: No Device Output | D39: 43905 | E39: It was reported that transmitter failed error occurred. Data was evaluated and the allegation was not confirmed. The probable cause could not be determined. No injury or medical intervention was reported | F39: Transmitter failed error => Could not determined the cause | G39: No
A40: 37 | B40: 9445-02 | C40: Wireless Communication Problem | D40: 43900 | E40: It was reported that signal loss over one hour occurred. A review of the share logs was performed and signal loss was found within the investigation window. The allegation was confirmed. The probable cause was the transmitter and app were unable to establish a connection. No injury or medical intervention was reported | F40: The signal loss was related to the mobile application => Due to Transmitter and app were unable establish a connection | G40: No
A41: 38 | B41: 9445-02 | C41: Wireless Communication Problem | D41: 43901 | E41: It was reported that signal loss over one hour occurred. A review of the share logs was performed and a loss of connection was not found within the investigation window. The allegation was not confirmed. The probable cause could not be determined. No injury or medical intervention was reported | F41: The signal loss was related to the mobile application => Could not determined the cause | G41: No
A42: 39 | B42: 9500-27 | C42: Break | D42: 43897 | E42: It was reported that a broken sensor wire occurred. The sensor was inserted into the abdomen on (b)(6) 2020. No product was provided for evaluation. Confirmation of the allegation and a probable cause could not be determined. No injury or medical intervention was reported | F42: Sensor wire broken => Could not determined the cause | G42: No
A43: 40 | B43: 9445-02 | C43: No Device Output | D43: 43905 | E43: It was reported that transmitter failed error occurred. No product or data was provided for evaluation. Confirmation of the allegation and a probable cause could not be determined. No injury or medical intervention was reported | F43: Transmitter failed error => Could not determined the cause | G43: No
A44: 41 | B44: N/A | C44: Wireless Communication Problem | D44: 43901 | E44: It was determined that the signal loss was related to the mobile application. It was indicated that the operating system for the smart device was not a supported system, which is off-label usage of the device. A review of the share logs was performed and signal loss was found within the investigation window. The allegation was confirmed. The probable cause could not be determined. No injury or medical intervention was reported | F44: The signal loss was related to the mobile application => Could not determined the cause | G44: No
A45: 42 | B45: 9445-02 | C45: No Device Output | D45: 43895 | E45: It was reported that transmitter failed error occurred. Data was evaluated and the allegation was confirmed. The probable cause was determined to be a low transmitter battery. No injury or medical intervention was reported | F45: Transmitter failed error => Due to battery of Transmitter was low | G45: No
A46: 43 | B46: N/A | C46: Wireless Communication Problem | D46: 43900 | E46: It was determined that the signal loss was related to the mobile application. It was indicated that the operating system for the smart device was not a supported system, which is off-label usage of the device. A review of the share logs was performed and signal loss was found within the investigation window. The allegation was confirmed. The probable cause was the patient closed the mobile app. No injury or medical intervention was reported | F46: The signal loss was related to the mobile application => Due to patient closed the mobile app | G46: No
... A63: 60 | B63: MT24078 | C63: Wireless Communication Problem | D63: 43901 | E63: It was reported that signal loss over one hour occurred. No product or data was provided for evaluation. Confirmation of the allegation and a probable cause could not be determined. No injury or medical intervention was reported. | F63: The signal loss was related to the mobile application => Could not determined the cause | G63: No
A64: 61 | B64: 9445-02 | C64: No Device Output | D64: 03/15/2020 | E64: It was reported that transmitter failed error occurred. Data was evaluated and the allegation was not confirmed. The probable cause could not be determined. No injury or medical intervention was reported. | F64: Transmitter failed error => Could not determined the cause | G64: No
A65: 62 | B65: 9445-02 | C65: Appropriate Term/Code Not Available | D65: 43908 | E65: It was reported that pair new transmitter alert occurred. Data was evaluated and the allegation was confirmed as a transmitter failed error. The probable cause was determined to be a transmitter failed error. The reported event of a pair new transmitter alert is reportable based on the finding of a transmitter failed error. No injury or medical intervention was reported. | F65: Transmitter failed error | G65: No
A66: 63 | B66: 9445-02 | C66: No Device Output | D66: 43904 | E66: It was reported that transmitter failed error occurred. Data was evaluated and the allegation was confirmed. The probable cause was determined to be a low transmitter battery. No injury or medical intervention was reported. | F66: Transmitter failed error => Due to battery of Transmitter was low | G66: No
A67: 64 | B67: 9500-45 | C67: Detachment of Device or device Component | D67: 43905 | E67: It was reported that a detached sensor wire occurred. The sensor was inserted into the abdomen on (b)(6) 2020. No product was provided for evaluation. Confirmation of the allegation and a probable cause could not be determined. No injury or medical intervention was reported. | F67: Missing or detached sensor wire => Could not determined the cause | G67: No
A68: 65 | B68: 9445-02 | C68: Wireless Communication Problem | D68: 43901 | E68: It was reported that signal loss over one hour occurred. No product or data was provided for evaluation. Confirmation of the allegation and a probable cause could not be determined. No injury or medical intervention was reported | F68: The signal loss was related to the mobile application => Could not determined the cause | G68: No
A69: 66 | B69: 9445-02 | C69: Wireless Communication Problem | D69: 43900 | E69: It was reported that signal loss over one hour occurred. A review of the share logs was performed and a loss of connection was found within the investigation window. However, the device operated within specification. The allegation was not confirmed. The probable cause could not be determined. No injury or medical intervention was reported. | F69: The signal loss was related to the mobile application => Could not determined the cause | G69: No
A70: 67 | B70: 9445-02 | C70: No Device Output | D70: 43902 | E70: It was reported that transmitter failed error occurred. Data was evaluated and the allegation was confirmed. The probable cause was determined to be a low transmitter battery. No injury or medical intervention was reported. | F70: Transmitter failed error => Due to battery of Transmitter was low | G70: No
A71: 68 | B71: 9445-02 | C71: No Device Output | D71: 43904 | E71: It was reported that transmitter failed error occurred. No product or data was provided for evaluation. Confirmation of the allegation and a probable cause could not be determined. No injury or medical intervention was reported. | F71: Transmitter failed error => Could not determined the cause | G71: No
A72: 69 | B72: 9438-06 | C72: No Device Output | D72: 43906 | E72: It was reported that transmitter failed error occurred. Data was evaluated and the allegation was confirmed. The probable cause was determined to be a low transmitter battery. No injury or medical intervention was reported. | F72: Transmitter failed error => Due to battery of Transmitter was low | G72: No
A73: 70 | B73: 9445-02 | C73: No Device Output | D73: 43904 | E73: It was reported that transmitter failed error occurred. Data was evaluated and the allegation was not confirmed. The probable cause could not be determined. No injury or medical intervention was reported. | F73: Transmitter failed error => Could not determined the cause | G73: No
...

Sheet Chart
A1: Summary
A3: No. | B3: Problem | C3: Problem | D3: Happened Times | E3: Rate (%) | F3: Rate (%)
A4: 1 | B4: Wireless Communication Problem | C4: Wireless Communication Problem | D4: =COUNTIF(Summary!$C$4:$C$484,C4) -> 229 | E4: =D4/SUM($D$4:$D$21) -> 0.48516949 | F4: =D4/SUM($D$4:$D$21) -> 0.48516949
A5: 2 | B5: No Device Output | C5: No Device Output | D5: 107 | E5: =D5/SUM($D$4:$D$21) -> 0.22669492 | F5: =D5/SUM($D$4:$D$21) -> 0.22669492
A6: 3 | B6: Imprecision | C6: Imprecision | D6: 60 | E6: =D6/SUM($D$4:$D$21) -> 0.12711864 | F6: =D6/SUM($D$4:$D$21) -> 0.12711864
A7: 4 | B7: Detachment of Device or device Component | C7: Detachment of Device or device Component | D7: 36 | E7: =D7/SUM($D$4:$D$21) -> 0.076271186 | F7: =D7/SUM($D$4:$D$21) -> 0.076271186
A8: 5 | B8: Appropriate Term/Code Not Available | C8: Appropriate Term/Code Not Available | D8: 6 | E8: =D8/SUM($D$4:$D$21) -> 0.012711864 | F8: =D8/SUM($D$4:$D$21) -> 0.012711864
A9: 6 | B9: Unintended Application Program Shut Down | C9: Unintended Application Program Shut Down | D9: 6 | E9: =D9/SUM($D$4:$D$21) -> 0.012711864 | F9: =D9/SUM($D$4:$D$21) -> 0.012711864
A10: 7 | B10: Defective Alarm | C10: Defective Alarm | D10: 5 | E10: =D10/SUM($D$4:$D$21) -> 0.01059322 | F10: =D10/SUM($D$4:$D$21) -> 0.01059322
A11: 8 | B11: Break | C11: Others | D11: 4 | E11: =D11/SUM($D$4:$D$21) -> 0.0084745763 | F11: =SUM(D11:D21)/SUM(D4:D21) -> 0.048728814
B12: Communication or Transmission Problem; Wireless Communication Problem | D12: 4 | E12: =D12/SUM($D$4:$D$21) -> 0.0084745763
B13: Failure to Sense | D13: 3 | E13: =D13/SUM($D$4:$D$21) -> 0.0063559322
B14: Alarm Not Visible | D14: 2 | E14: =D14/SUM($D$4:$D$21) -> 0.0042372881
B15: Device Displays Incorrect Message | D15: 2 | E15: =D15/SUM($D$4:$D$21) -> 0.0042372881
B16: Premature End-of-Life Indicator | D16: 2 | E16: =D16/SUM($D$4:$D$21) -> 0.0042372881
B17: Unable to Obtain Readings | D17: 2 | E17: =D17/SUM($D$4:$D$21) -> 0.0042372881
B18: Communication or Transmission Problem | D18: 1 | E18: =D18/SUM($D$4:$D$21) -> 0.0021186441
B19: Device Output | D19: 1 | E19: =D19/SUM($D$4:$D$21) -> 0.0021186441
B20: Overheating of Device | D20: 1 | E20: =D20/SUM($D$4:$D$21) -> 0.0021186441
B21: Unexpected Shutdown | D21: 1 | E21: =D21/SUM($D$4:$D$21) -> 0.0021186441
A30: 1. Wireless Communication Problem
A32: No. | C32: Problem / Cause | F32: Happened time | G32: Ratio (%)
A33: 1 | C33: Intermittent loss of connection issues occurred between the transmitter and the pump => Replaced a new Transmitter | F33: =COUNTIF(Summary!$F$4:$F$484,Chart!C33) -> 9 | G33: =F33/SUM($F$33:$F$42) -> 0.038626609
A34: 2 | C34: Loss of connection was related to the mobile application => Could not determined the cause | F34: =COUNTIF(Summary!$F$4:$F$484,Chart!C34) -> 16 | G34: =F34/SUM($F$33:$F$42) -> 0.068669528
A35: 3 | C35: The bluetooth connection between transmitter and mobile app issue occurred => Could not determined the cause | F35: =COUNTIF(Summary!$F$4:$F$484,Chart!C35) -> 8 | G35: =F35/SUM($F$33:$F$42) -> 0.034334764
A36: 4 | C36: The signal loss was related to the mobile application => A follow up report will be submitted upon completion | F36: =COUNTIF(Summary!$F$4:$F$484,Chart!C36) -> 2 | G36: =F36/SUM($F$33:$F$42) -> 0.008583691
A37: 5 | C37: The signal loss was related to the mobile application => Could not determined the cause | F37: =COUNTIF(Summary!$F$4:$F$484,Chart!C37) -> 157 | G37: =F37/SUM($F$33:$F$42) -> 0.67381974
A38: 6 | C38: The signal loss was related to the mobile application => Due to mobile device lost power | F38: =COUNTIF(Summary!$F$4:$F$484,Chart!C38) -> 1 | G38: =F38/SUM($F$33:$F$42) -> 0.0042918455
A39: 7 | C39: The signal loss was related to the mobile application => Due to patient closed the mobile app | F39: =COUNTIF(Summary!$F$4:$F$484,Chart!C39) -> 7 | G39: =F39/SUM($F$33:$F$42) -> 0.030042918
A40: 8 | C40: The signal loss was related to the mobile application => Due to Transmitter and app were unable establish a connection | F40: =COUNTIF(Summary!$F$4:$F$484,Chart!C40) -> 22 | G40: =F40/SUM($F$33:$F$42) -> 0.094420601
A41: 9 | C41: The signal loss was related to the mobile application => The allegation was confirmed | F41: =COUNTIF(Summary!$F$4:$F$484,Chart!C41) -> 1 | G41: =F41/SUM($F$33:$F$42) -> 0.0042918455
A42: 10 | C42: The signal loss was related to the mobile application => The transmitter ultimately regained connection with the pump | F42: =COUNTIF(Summary!$F$4:$F$484,Chart!C42) -> 10 | G42: =F42/SUM($F$33:$F$42) -> 0.042918455
