Workbook

Sheet Sheet1
A1: ORGANISATION CHART OF M&C IN OCT.1ST
J3: Vice G.D
J4: Lee Hyung Jong
D6: General production | P6: General Management
D7: Kim Young Jin | P7: Lee Hyun Jong
A10: Cast team | D10: CNC team | G10: Post processing team | J10: Pro. Management team | M10: Management team | P10: Purchasing team | S10: Sales team | V10: Cosmetics team | Y10: R&D team | AB10: QC team
A11: Cho Dong Moon | D11: Jeon Inh Wan Mr Chat | G11: Li Shao Hui | J11: Lim Jung Jin | M11: Choi Byoung Youn | P11: Choi Byoung Youn | S11: Lee Jae Gan | V11: Lee Choong Jea | Y11: Lee Choong Jea | AB11: Kim ByoungKwan
A14: Die-casting | G14: Polishing/ Chromate | J14: Pro.plan | M14: Accounting | P14: Purchase | S14: Sales team | V14: Production design | Y14: R&D | AB14: QC
A15: Kim Ju Seok Mr Tan | G15: Mr Thoa | J15: Ms Bich | M15: Ms Chi | P15: Ms Hoan | S15: Lee Jin Ho | V15: Ms Hue | Y15: Mr Koh | AB15: Mr Nguyen
A18: Mold -Trimming | G18: Paiting /Pad/UV | J18: F.warehouse | M18: HR | P18: R&D purchase | V18: Production tech | Y18: R&D | AB18: IQC
A19: Mr Manh | G19: Mr Ha | J19: Mr Quyet | M19: Ms Thom | P19: Ms Hoa | V19: Mr Cuong | Y19: Mr Lee Jae Seok | AB19: Ms Nguyet
A22: Extrusion | G22: Assembly/ nail | J22: Mat.warehouse | M22: GA | AB22: OQC/CS
A23: Mr Hung | G23: Ms Quyen | J23: Mr Duy | M23: Mr Duc | AB23: Mr Huong
A26: Injection | G26: Cosmetics | J26: Scrap | M26: EHS | AB26: PQC
A27: Mr Khanh | G27: Ms Sinh | J27: Mr Duan | M27: Mr Son | AB27: Mr Dat
A30: Utility | M30: Log
A31: Mr Dai | M31: Ms Bien

Sheet Sheet1 (2)
A1: ORGANISATION CHART OF M&C IN MAR.14th
J3: Vice G.D
J4: Lee Hyun Jong
D6: General production | Y6: General R&D
D7: Kim Young Jin | Y7: Lee Choong Jea
A10: Cast team | D10: CNC team | G10: Post processing team | J10: Pro. Management team | M10: Management team | P10: Purchasing team | S10: Sales team | V10: R&D | Y10: R&D | AB10: QC team
A11: Cho Dong Moon | D11: Jeon Inh Wan Mr Chat | G11: Li Shao Hui | J11: Lim Jung Jin | M11: Choi Byoung Youn | P11: Choi Byoung Youn | S11: Lee Jae Gan | V11: Mr Koh | Y11: Mr Koh | AB11: Kim ByoungKwan
A14: Die-casting | D14: CNC team | G14: Polishing/ Chromate | J14: Pro.plan | M14: HR | P14: Log | S14: Sales team | V14: Production design | Y14: R&D | AB14: QC
A15: Kim Ju Seok Mr Tan | D15: Mr Chat | G15: Mr Thoa | J15: Ms Bich | M15: Ms Thom | P15: Ms Hanh | S15: Lee Jin Ho | V15: Ms Hue | Y15: Mr Lee Jae Seok | AB15: Mr Tan
A18: Mold -Trimming | G18: Paiting /Nail/Pad/UV | J18: Mat.warehouse | M18: Act | P18: Purchase | S18: Sales team | V18: Production tech | Y18: R&D
A19: Mr Manh | G19: Mr Hung | J19: Mr Duy | M19: Ms Chi | P19: Ms Hoa | S19: Ms Ket | V19: Mr Cuong | Y19: Mr Dan
A22: Injection | G22: Assembly/ MME | J22: Scrap | M22: GA | S22: F.warehouse
A23: Mr Khanh | G23: Ms Quyen | J23: Mr Duan | M23: Mr Duc | S23: Mr Quyet
M26: EHS
M27: Mr Son
M30: Utility
M31: Mr Dai

Sheet SDTC 1.1
A1: SƠ ĐỒ TỔ CHỨC CÔNG TY TNHH M&C ELECTRONIC VINA 2019
F2: M&C Organization chart 2019
N6: Vice G.D
N7: Lee Hyung Jong
E8: General production | Z8: General R&D
E9: Kim Young Jin | Z9: Lee Choong Jea
B12: Cast team | E12: CNC team | H12: Post processing team | K12: Pro. Management team | N12: Management team | Q12: Purchasing team | T12: Sales team | W12: R&D | Z12: R&D | AC12: QC team
B13: Cho Dong Mun | E13: Jeon Inh Wan | H13: Li Shao Hui | K13: Lim Jung Jin | N13: Choi Byoung Youn | Q13: Choi Byoung Youn | T13: Lee Jae Gan | W13: Mr Koh | Z13: Mr Koh | AC13: Kim ByoungKwan
B16: Die-casting | E16: CNC team | H16: Polishing/ Chromate | K16: Pro.plan | N16: HR | Q16: Log | T16: Sales team | W16: Production design | Z16: R&D | AC16: QC
B17: Kim Ju Seok | E17: Mr Chat | H17: Mr Thoa | K17: Ms Bich | N17: Ms Thom | Q17: Ms Hanh | T17: Lee Jin Ho | W17: Ms Hue | Z17: Mr Lee Jae Seok | AC17: Mr Tan
B20: Mold -Trimming | H20: Paiting /Nail/Pad/UV | K20: Mat.warehouse | N20: Acct | Q20: Purchase | T20: Sales team | W20: Production tech | Z20: R&D | AC20: CS
B21: Mr Manh | H21: Mr Hà | K21: Mr Duy | N21: Ms Chi | Q21: Ms Hoa | T21: Ms Ket | W21: Mr Cuong | Z21: Mr Dan | AC21: Mr.Hưởng
B24: Injection | H24: Assembly/ MME | K24: Scrap | N24: GA | T24: F.warehouse
B25: Mr Khanh | H25: Ms Quyen | K25: Mr Duan | N25: Mr Duc | T25: Mr Quyet
N28: EHS
N29: Mr Son
N32: Utility
N33: Mr Dai

Sheet SDTC 17.8
A1: SƠ ĐỒ TỔ CHỨC CÔNG TY TNHH M&C ELECTRONIC VINA 2019
F2: M&C Organization chart 2019
N6: Vice G.D
N7: Lee Hyung Jong
E8: General production | Z8: General R&D
E9: Kim Young Jin | Z9: Lee Choong Jea
B12: Cast team | E12: CNC team | H12: Post processing team | K12: Pro. Management team | N12: Management team | Q12: Purchasing team | T12: Sales team | W12: R&D | Z12: R&D | AC12: QC team
B13: Cho Dong Mun | E13: Jeon Inh Wan | H13: Li Shao Hui | K13: Lim Jung Jin | N13: Choi Byoung Youn | Q13: Choi Byoung Youn | T13: Lee Jae Gan | W13: Mr Koh | Z13: Mr Koh | AC13: Kim ByoungKwan
B16: Die-casting | E16: CNC team | H16: Polishing/ Chromate | K16: Pro.plan | N16: HR | Q16: Log | T16: Sales team | W16: Production design | Z16: R&D | AC16: QC
B17: Kim Ju Seok | E17: Mr Chat | H17: Mr Thoa | K17: Ms Bich | N17: Ms Thom | Q17: Ms Hanh | T17: Lee Jin Ho | W17: Ms Hue | Z17: Mr Lee Jae Seok | AC17: Mr Tan
B20: Mold -Trimming | H20: Paiting /Nail/Pad/UV | K20: Mat.warehouse | N20: Acct | Q20: Purchase | T20: Sales team | W20: Production tech | Z20: R&D | AC20: CS
B21: Mr Manh | H21: Mr Thanh | K21: Mr Duy | N21: Ms Chi | Q21: Ms Hoa | T21: Ms Ket | W21: Mr Cuong | Z21: Mr Dan | AC21: Mr.Viet
B24: Injection | H24: Assembly/ MME | K24: Scrap | N24: GA | T24: F.warehouse
B25: Mr Khanh | H25: Ms Quyen | K25: Mr Duan | N25: Mr Duc | T25: Mr Quyet
N28: EHS
N29: Mr Son
N32: Utility
N33: Mr Dai

Sheet Sheet2
B3: Phê duyệt | C3: Lập | D3: Kiểm tra | E3: Phê duyệt
B6: Mã số QL | D6: GA.03.00.04 Ngày ban hành 01/01/2019

Sheet Sheet3

Sheet 17.6
D1: SƠ ĐỒ TỔ CHỨC CÔNG TY TNHH M&C ELECTRONIC VINA 2021 M&C Organization chart 2021 | AB1: Issue by | AD1: Check by | AF1: Approval by
AB2: Ms Hang | AD2: Ms Thom | AF2: Mr Kim
AB4: 44295 | AD4: 44295 | AF4: 44295
Q7: Vice G.D
Q8: Kim Young Jin Tel :+84-904-057-136 yj.kim@mnce.biz
E11: Cast & Trimming team | Q11: GA- HR Management team | X11: General R&D | AD11: Sales -QC
E12: Cho Dong Mun Tel : +84-772-229-088 dm.cho@mnce.biz | Q12: Choi Byoung Youn Tel :+84-0936-137-210 by.choi@mnce.biz | X12: Lee Choong Jae Tel: +84-0772-273-111 cj.lee@mnce.biz | AD12: Mr Joung Ui Young +84-0906-007-075 uyjoung@mnce.biz
B15: Die-casting Management | E15: CNC team | H15: Post processing Management team | N15: HR Senior Management | Q15: Purchase Management | T15: Acct Management | W15: R&D Management team Cosmetic & mobile | Z15: R&D Automotive | AC15: Sales Management team | AF15: QC Management team
B16: Kim Ju Seok +84-936-537-009 juseok.kim@mnce.biz | E16: Jeon Inh Wan Tel : +84-772-384-333 dlsghks4157@naver.com | H16: Li Shao Hui Tel: +84-904-585-173 shaohui.li@mnce.biz | N16: Nguyen Huong Thom +84-983-028-566 nh.thom@mncw.biz | Q16: Pham Thi Hoan +84-936-664-588 pt.hoan@mnce.biz | T16: Ta Khanh Chi Tel :+84-0912-240-251 tk.chi@mnce.biz | W16: Mr Koh Jin Suk Tel :+84-0702-231-199 js.koh@mnce.biz | Z16: Mr Min Sungki +84-0902-013-665 SUNGKI.MIN@mnce.biz | AC16: Fang Youngze Tel :+86-1862-2355-230 yongze.fang@mnce.biz | AF16: Mr Kim ByoungKwan +84-0705-888-099 bk.kim@mnce.biz
B19: Die-casting Management | E19: CNC Automation | H19: Paiting /Nail/Pad/UV A.Management | K19: Pro.plan Management | N19: GA Senior Management | W19: Management | AC19: Sales Management | AF19: QC .Management
B20: Hoang Ngoc Quoc Tan +84-976-008-886 hq.tan@mnce.biz | E20: Mr Zhaopeng Wang +84-820-889-208 zhaopeng.wang@mnce.biz | H20: Dang Van Thanh +84-978-923-207 nt.thanh@mnce.biz | K20: Tran Thi Thuy +84-977-337-670 tt.thuy@mnce.biz | N20: Ngo Van Dong Duc +84-982-098-850 nd.duc@mnce.biz | W20: Mr Lee Jae Seok +84-0766-443-668 js.lee@mnce.biz | AC20: Lee Jin Ho +84-0789-220-111 jin@mnce.biz | AF20: Nguyen The Duan +84-369-590-858 nt.duan@mnce.biz
B23: Mold -Trimming Management | E23: CNC Management | H23: Assembly/ MME A.Management | K23: Mat.warehouse staff | N23: EHS Management | W23: Management | AC23: Sales Management | AF23: QC A.Management
B24: Nguyen Ngoc Manh +84-971 -470- 487 nn.manh@mnce.biz | E24: Nguyen Van Chat +84-917-430-569 nv.chat@mnce.biz | H24: Doan Thi To Quyen +84-979-328-931 dt.quyen@mnc.biz | K24: Nguyen Phuong Duy +84-971-732-234 np.duy@mnce.biz | N24: Nguyen Van Tu +84-982-268-796 nv.tu@mnce.biz | W24: Nguyen Khac Dan +84-941-428-841 nk.dan@mnce.biz | AC24: Hoang Van Thang +84-0919-457-988 hv.thang@mnce.biz | AF24: Dao Van Tan +84-972-008-973 dv.tan@mnce.biz
B27: Injection Management | H27: Polishing/Hotpress/Non-chromate/nail -Shift leader | K27: Scrap staff | N27: Utility Management | W27: A.Management | AF27: CS A.Management
B28: Nguyen Van Tu +84-972-794-495 nv.tu@mnce.biz | H28: Tran Van Hung +84-984-265-951 tv.hung@mnc.biz | K28: Hoang Van Duan +84-967-161-107 hv.duan@mnce.biz | N28: Nguyen Ngoc Dai +84-968-043-086 nn.dai@mnce.biz | W28: Nguyen Viet Cuong +84-0949-117-290 nv.cuong@mnce.biz | AF28: Nguyen The San +84-973-261-412 nt.san@mnce.biz
B31: Injection A.Management | K31: Pro.warehouse staff | N31: Automation | AF31: QA
B32: Dao Ngoc Khanh +84-962-987-943 dn.khanh@mnce.biz | K32: Nguyen Duc Quyet +84-343-391-666 nf.quyet@mnce.biz | N32: Mr Thang +84-0363-780-395 pv.thang@mnce.biz | AF32: Khuc Thi Hau +84-985-114-505 kt.hau@mnce.biz
N34: IT
N35: Mr Luong +84-0902-007-702 nl.luong@mnce.biz
B37: Position | E37: Cast Management team (Đúc, Dập, Khuôn, Đúc nhựa) | H37: CNC Management team (CNC) | K37: Post processing Management team (Mài, XLHH, Sơn, Inpad, Mi giả, LR, CHN, Nail, GC) | N37: Pro. Management team (Kế hoạch, kho NVL, Kho TP) | Q37: GA- HR Management team (HR-GA, Cơ điện, EHS,IT) | T37: Accounting team | W37: Purchasing Management team (PUR) | Z37: Sales Management team Kinh doanh | AC37: R&D Management team | AF37: QC Management team | AH37: Total
B38: Team leader (Korea) | E38: 2 | H38: 1 | K38: 1 | N38: 0 | Q38: 1 | T38: 0 | W38: 0 | Z38: 2 | AC38: 4 | AF38: 2 | AH38: =+SUM(E38:AG38) -> 13
B39: Manager | E39: 3 | H39: 1 | K39: 0 | N39: 1 | Q39: 5 | T39: 1 | W39: 1 | Z39: 2 | AC39: 2 | AF39: 1 | AH39: =+SUM(E39:AG39) -> 17
B40: A. Manager | E40: 3 | H40: 1 | K40: 1 | N40: 0 | Q40: 5 | T40: 0 | W40: 2 | Z40: 1 | AC40: 3 | AF40: 2 | AH40: =+SUM(E40:AG40) -> 18
B41: Senior staff | E41: 5 | H41: 3 | K41: 4 | N41: 4 | Q41: 8 | T41: 2 | W41: 0 | Z41: 1 | AC41: 8 | AF41: 4 | AH41: =+SUM(E41:AG41) -> 39
B42: Staff | E42: 3 | H42: 1 | K42: 3 | N42: 5 | Q42: 3 | T42: 3 | W42: 1 | Z42: 1 | AC42: 3 | AF42: 10 | AH42: =+SUM(E42:AG42) -> 33
B43: Technical | E43: 30 | H43: 11 | K43: 20 | N43: 2 | Q43: 15 | T43: 0 | W43: 0 | Z43: 0 | AC43: 8 | AF43: 0 | AH43: =+SUM(E43:AG43) -> 86
B44: Worker | E44: 89 | H44: 179 | K44: 141 | N44: 7 | Q44: 9 | T44: 0 | W44: 0 | Z44: 0 | AC44: 1 | AF44: 64 | AH44: =+SUM(E44:AG44) -> 490
B45: Total | E45: =+SUM(E38:E44) -> 135 | H45: =+SUM(H38:H44) -> 197 | K45: =+SUM(K38:K44) -> 170 | N45: =+SUM(N38:N44) -> 19 | Q45: =+SUM(Q38:Q44) -> 46 | T45: =+SUM(T38:T44) -> 6 | W45: =+SUM(W38:W44) -> 4 | Z45: =+SUM(Z38:Z44) -> 7 | AC45: =+SUM(AC38:AC44) -> 29 | AF45: =+SUM(AF38:AF44) -> 83 | AH45: =+SUM(E45:AG45) -> 696 | AI45: =AH45-AH38 -> 683

Sheet Sheet4
D11: Phê duyệt | E11: Lập | F11: Kiểm tra | G11: Phê duyệt
E12: Ms Hậu | F12: Mr Kim | G12: Mr Lee
E13: 20.Nov.2019 | F13: 20.Nov.2019 | G13: 20.Nov.2019

Sheet total
A1: ID | B1: Họ và tên Full name | C1: Ngày vào Join-date | D1: Giới tính Sex | E1: Phòng ban Dept | F1: Vị trí Position | G1: Tình trạng Status | H1: Ngày nghỉ việc Resign date
A2: 9156 | B2: ĐẶNG Ý THĂNG | E2: Cast Management team | F2: Technical
A3: 9157 | B3: ĐỖ THỊ THÚY | E3: QC Management team | F3: Worker
A4: 9158 | B4: NGUYỄN THỊ ĐỊNH | E4: CNC Management team | F4: Worker
A5: 9159 | B5: VI THỊ PHƯỢNG | E5: CNC Management team | F5: Worker
A6: 9160 | B6: NGUYỄN VĂN LAM | E6: CNC Management team | F6: Worker
A7: 9161 | B7: NGUYỄN VĂN MẠNH | E7: CNC Management team | F7: Worker
A8: 9162 | B8: VI VĂN TƯ | E8: CNC Management team | F8: Worker
A9: 9163 | B9: HÀ VĂN THƯỜNG | E9: CNC Management team | F9: Worker
A10: 9164 | B10: NGUYỄN VĂN HÀ | E10: CNC Management team | F10: Worker
A11: 9165 | B11: HÀ VIỆT HÒA | E11: CNC Management team | F11: Worker
A12: 9166 | B12: BÙI VĂN CHƯƠNG | E12: CNC Management team | F12: Worker
A13: 9167 | B13: LƯƠNG VĂN XUÂN | E13: CNC Management team | F13: Worker
... A35: 9192 | B35: BÙI VĂN BÌNH | E35: QC Management team | F35: Worker
A36: 9133 | B36: NGUYỄN TÀI THƯỞNG | C36: =VLOOKUP(A36,'[1]Danh sach tong '!$B$3:$I$8057,3,0) -> 5/5/2020 | D36: =VLOOKUP(A36,'[1]Danh sach tong '!$B$3:$I$8057,4,0) -> Nam | E36: R&D Management team | F36: Staff
A37: 9135 | B37: NGUYỄN THỊ ÁNH TUYẾT | C37: =VLOOKUP(A37,'[1]Danh sach tong '!$B$3:$I$8057,3,0) -> 1/6/2020 | D37: =VLOOKUP(A37,'[1]Danh sach tong '!$B$3:$I$8057,4,0) -> Nữ | E37: GA- HR Management team | F37: Staff
A38: 9137 | B38: NHẠC VĂN DŨNG | C38: =VLOOKUP(A38,'[1]Danh sach tong '!$B$3:$I$8057,3,0) -> 3/6/2020 | D38: =VLOOKUP(A38,'[1]Danh sach tong '!$B$3:$I$8057,4,0) -> Nam | E38: Cast Management team | F38: Worker
A39: 9138 | B39: MA VĂN TRƯỜNG | C39: =VLOOKUP(A39,'[1]Danh sach tong '!$B$3:$I$8057,3,0) -> 3/6/2020 | D39: =VLOOKUP(A39,'[1]Danh sach tong '!$B$3:$I$8057,4,0) -> Nam | E39: Cast Management team | F39: Worker
A40: 9139 | B40: LÌU VĂN ĐỨC | C40: =VLOOKUP(A40,'[1]Danh sach tong '!$B$3:$I$8057,3,0) -> 3/6/2020 | D40: =VLOOKUP(A40,'[1]Danh sach tong '!$B$3:$I$8057,4,0) -> Nam | E40: Cast Management team | F40: Worker
A41: 9142 | B41: QUANG VĂN LINH | C41: =VLOOKUP(A41,'[1]Danh sach tong '!$B$3:$I$8057,3,0) -> 4/6/2020 | D41: =VLOOKUP(A41,'[1]Danh sach tong '!$B$3:$I$8057,4,0) -> Nam | E41: Cast Management team | F41: Worker
A42: 9143 | B42: NGUYỄN ANH TIẾN | C42: =VLOOKUP(A42,'[1]Danh sach tong '!$B$3:$I$8057,3,0) -> 4/6/2020 | D42: =VLOOKUP(A42,'[1]Danh sach tong '!$B$3:$I$8057,4,0) -> Nam | E42: Cast Management team | F42: Worker
A43: 9146 | B43: DƯƠNG DOÃN CHI | C43: =VLOOKUP(A43,'[1]Danh sach tong '!$B$3:$I$8057,3,0) -> 5/6/2020 | D43: =VLOOKUP(A43,'[1]Danh sach tong '!$B$3:$I$8057,4,0) -> Nam | E43: Cast Management team | F43: Worker
A44: 9150 | B44: BÙI THỌ OÁNH | C44: =VLOOKUP(A44,'[1]Danh sach tong '!$B$3:$I$8057,3,0) -> 5/6/2020 | D44: =VLOOKUP(A44,'[1]Danh sach tong '!$B$3:$I$8057,4,0) -> Nam | E44: Cast Management team | F44: Worker
A45: 9151 | B45: SÙNG A SÊNH | C45: =VLOOKUP(A45,'[1]Danh sach tong '!$B$3:$I$8057,3,0) -> 5/6/2020 | D45: =VLOOKUP(A45,'[1]Danh sach tong '!$B$3:$I$8057,4,0) -> Nam | E45: Cast Management team | F45: Worker
A46: 9152 | B46: NGỌC VĂN TUÂN | C46: =VLOOKUP(A46,'[1]Danh sach tong '!$B$3:$I$8057,3,0) -> 5/6/2020 | D46: =VLOOKUP(A46,'[1]Danh sach tong '!$B$3:$I$8057,4,0) -> Nam | E46: Cast Management team | F46: Worker
A47: 9153 | B47: MAI ĐÌNH ANH | C47: =VLOOKUP(A47,'[1]Danh sach tong '!$B$3:$I$8057,3,0) -> 5/6/2020 | D47: =VLOOKUP(A47,'[1]Danh sach tong '!$B$3:$I$8057,4,0) -> Nam | E47: Cast Management team | F47: Worker
... A49: 9155 | B49: ĐINH VĂN MINH | C49: =VLOOKUP(A49,'[1]Danh sach tong '!$B$3:$I$8057,3,0) -> 5/6/2020 | D49: =VLOOKUP(A49,'[1]Danh sach tong '!$B$3:$I$8057,4,0) -> Nam | E49: Cast Management team | F49: Technical
A51: 1002 | B51: PHẠM THỊ HOÀN | C51: 20/06/2013 | D51: Nữ | E51: Accounting team | F51: Manager
A52: 1003 | B52: NGUYỄN THỊ HƯƠNG THƠM | C52: 13/12/2013 | D52: Nữ | E52: GA- HR Management team | F52: Manager
A53: 1007 | B53: NGUYỄN NGỌC MẠNH | C53: 24/11/2013 | D53: Nam | E53: Cast Management team | F53: Manager
A54: 1037 | B54: ĐẶNG THỊ HOÀNG HOA | C54: 20/3/2014 | D54: Nữ | E54: Purchasing Management team PUR | F54: Manager
A55: 1052 | B55: NGUYỄN THỊ TRANG | C55: 7/7/2014 | D55: Nữ | E55: Post processing Management team | F55: Worker | L55: =28000000000000/23000 -> 1.2173913e+09
A56: 1054 | B56: PHẠM THỊ HÒE | C56: 7/7/2014 | D56: Nữ | E56: Post processing Management team | F56: Staff
A57: 1063 | B57: NGUYỄN VĂN LƯU | C57: 7/7/2014 | D57: Nam | E57: CNC Management team | F57: Worker
A58: 1080 | B58: TRẦN VĂN HÙNG | C58: 10/7/2014 | D58: Nam | E58: Post processing Management team | F58: Senior staff
A59: 1082 | B59: ĐÀO HỮU VIẾT | C59: 12/7/2014 | D59: Nam | E59: Cast Management team | F59: Senior staff
A60: 1087 | B60: ĐẶNG VĂN THANH | C60: 15/7/2014 | D60: Nam | E60: Post processing Management team | F60: A. Manager
A61: 1100 | B61: NGUYỄN THỊ LUẬN | C61: 23/7/2014 | D61: Nữ | E61: Pro. Management team | F61: Senior staff
A62: 1103 | B62: NGUYỄN THỊ HÀ | C62: 1/8/2014 | D62: Nữ | E62: R&D Management team | F62: Senior staff
A63: 1113 | B63: NGHIÊM XUÂN TUYÊN | C63: 11/8/2014 | D63: Nam | E63: Pro. Management team | F63: Worker
...

Sheet Sheet6
A3: Count of Họ và tên Full name | B3: Column Labels
A4: Row Labels | B4: Accounting team | C4: GA- HR Management team | D4: Cast Management team | E4: Purchasing Management team PUR | F4: Post processing Management team | G4: CNC Management team | H4: Pro. Management team | I4: R&D Management team | J4: Sales Management team | K4: QC Management team | L4: (blank) | M4: Grand Total
A5: Manager | B5: 2 | C5: 5 | D5: 2 | E5: 1 | G5: 1 | I5: 1 | J5: 2 | K5: 2 | M5: 16
A6: Worker | C6: 1 | D6: 71 | F6: 184 | G6: 163 | H6: 10 | I6: 3 | K6: 48 | M6: 480
A7: Staff | B7: 2 | C7: 6 | D7: 2 | E7: 1 | F7: 5 | G7: 1 | H7: 6 | I7: 4 | J7: 1 | K7: 7 | M7: 35
A8: Senior staff | B8: 1 | C8: 7 | D8: 3 | E8: 2 | F8: 2 | G8: 6 | H8: 2 | I8: 7 | J8: 2 | K8: 7 | M8: 39
A9: A. Manager | B9: 1 | C9: 3 | D9: 3 | F9: 3 | H9: 1 | I9: 3 | J9: 1 | K9: 2 | M9: 17
A10: Technical | C10: 9 | D10: 26 | F10: 18 | G10: 11 | H10: 3 | I10: 6 | M10: 73
A11: (blank)
A12: Grand Total | B12: 6 | C12: 31 | D12: 107 | E12: 4 | F12: 212 | G12: 182 | H12: 22 | I12: 24 | J12: 6 | K12: 66 | M12: 660

Sheet so lieu update
A3: Position | B3: Cast Management team | C3: CNC Management team | D3: Post processing Management team | E3: Pro. Management team | F3: GA- HR Management team | G3: Accounting team | H3: Purchasing Management team PUR | I3: Sales Management team | J3: R&D Management team | K3: QC Management team | L3: Total
A4: Korean manager | B4: 3 | C4: 2 | D4: 1 | E4: 0 | F4: 1 | G4: 1 | H4: 0 | I4: 2 | J4: 4 | K4: 2 | L4: =SUM(B4:K4) -> 16
A5: Manager | B5: =GETPIVOTDATA("Họ và tên Full name",Sheet6!$A$3,"Phòng ban Dept","Cast Management team","Vị trí Position","Manager") -> 2 | C5: =GETPIVOTDATA("Họ và tên Full name",Sheet6!$A$3,"Phòng ban Dept","CNC Management team","Vị trí Position","Manager") -> 1 | D5: =GETPIVOTDATA("Họ và tên Full name",Sheet6!$A$3,"Phòng ban Dept","Post processing Management team","Vị trí Position","Manager") -> 0 | E5: =GETPIVOTDATA("Họ và tên Full name",Sheet6!$A$3,"Phòng ban Dept","Pro. Management team","Vị trí Position","Manager") -> 0 | F5: =GETPIVOTDATA("Họ và tên Full name",Sheet6!$A$3,"Phòng ban Dept","GA- HR Management team","Vị trí Position","Manager") -> 5 | G5: =GETPIVOTDATA("Họ và tên Full name",Sheet6!$A$3,"Phòng ban Dept","Accounting team","Vị trí Position","Manager") -> 2 | H5: =GETPIVOTDATA("Họ và tên Full name",Sheet6!$A$3,"Phòng ban Dept","Purchasing Management team PUR","Vị trí Position","Manager") -> 1 | I5: =GETPIVOTDATA("Họ và tên Full name",Sheet6!$A$3,"Phòng ban Dept","Sales Management team","Vị trí Position","Manager") -> 2 | J5: =GETPIVOTDATA("Họ và tên Full name",Sheet6!$A$3,"Phòng ban Dept","R&D Management team","Vị trí Position","Manager") -> 1 | K5: =GETPIVOTDATA("Họ và tên Full name",Sheet6!$A$3,"Phòng ban Dept","QC Management team","Vị trí Position","Manager") -> 2 | L5: =SUM(B5:K5) -> 16
A6: A. Manager | B6: =GETPIVOTDATA("Họ và tên Full name",Sheet6!$A$3,"Phòng ban Dept","Cast Management team","Vị trí Position","A. Manager") -> 3 | C6: =GETPIVOTDATA("Họ và tên Full name",Sheet6!$A$3,"Phòng ban Dept","CNC Management team","Vị trí Position","A. Manager") -> 0 | D6: =GETPIVOTDATA("Họ và tên Full name",Sheet6!$A$3,"Phòng ban Dept","Post processing Management team","Vị trí Position","A. Manager") -> 3 | E6: =GETPIVOTDATA("Họ và tên Full name",Sheet6!$A$3,"Phòng ban Dept","Pro. Management team","Vị trí Position","A. Manager") -> 1 | F6: =GETPIVOTDATA("Họ và tên Full name",Sheet6!$A$3,"Phòng ban Dept","GA- HR Management team","Vị trí Position","A. Manager") -> 3 | G6: =GETPIVOTDATA("Họ và tên Full name",Sheet6!$A$3,"Phòng ban Dept","Accounting team","Vị trí Position","A. Manager") -> 1 | H6: =GETPIVOTDATA("Họ và tên Full name",Sheet6!$A$3,"Phòng ban Dept","Purchasing Management team PUR","Vị trí Position","A. Manager") -> 0 | I6: =GETPIVOTDATA("Họ và tên Full name",Sheet6!$A$3,"Phòng ban Dept","Sales Management team","Vị trí Position","A. Manager") -> 1 | J6: =GETPIVOTDATA("Họ và tên Full name",Sheet6!$A$3,"Phòng ban Dept","R&D Management team","Vị trí Position","A. Manager") -> 3 | K6: =GETPIVOTDATA("Họ và tên Full name",Sheet6!$A$3,"Phòng ban Dept","QC Management team","Vị trí Position","A. Manager") -> 2 | L6: =SUM(B6:K6) -> 17
A7: Senior staff | B7: =GETPIVOTDATA("Họ và tên Full name",Sheet6!$A$3,"Phòng ban Dept","Cast Management team","Vị trí Position","Senior staff") -> 3 | C7: =GETPIVOTDATA("Họ và tên Full name",Sheet6!$A$3,"Phòng ban Dept","CNC Management team","Vị trí Position","Senior staff") -> 6 | D7: =GETPIVOTDATA("Họ và tên Full name",Sheet6!$A$3,"Phòng ban Dept","Post processing Management team","Vị trí Position","Senior staff") -> 2 | E7: =GETPIVOTDATA("Họ và tên Full name",Sheet6!$A$3,"Phòng ban Dept","Pro. Management team","Vị trí Position","Senior staff") -> 2 | F7: =GETPIVOTDATA("Họ và tên Full name",Sheet6!$A$3,"Phòng ban Dept","GA- HR Management team","Vị trí Position","Senior staff") -> 7 | G7: =GETPIVOTDATA("Họ và tên Full name",Sheet6!$A$3,"Phòng ban Dept","Accounting team","Vị trí Position","Senior staff") -> 1 | H7: =GETPIVOTDATA("Họ và tên Full name",Sheet6!$A$3,"Phòng ban Dept","Purchasing Management team PUR","Vị trí Position","Senior staff") -> 2 | I7: =GETPIVOTDATA("Họ và tên Full name",Sheet6!$A$3,"Phòng ban Dept","Sales Management team","Vị trí Position","Senior staff") -> 2 | J7: =GETPIVOTDATA("Họ và tên Full name",Sheet6!$A$3,"Phòng ban Dept","R&D Management team","Vị trí Position","Senior staff") -> 7 | K7: =GETPIVOTDATA("Họ và tên Full name",Sheet6!$A$3,"Phòng ban Dept","QC Management team","Vị trí Position","Senior staff") -> 7 | L7: =SUM(B7:K7) -> 39
A8: Staff | B8: =GETPIVOTDATA("Họ và tên Full name",Sheet6!$A$3,"Phòng ban Dept","Cast Management team","Vị trí Position","Staff") -> 2 | C8: =GETPIVOTDATA("Họ và tên Full name",Sheet6!$A$3,"Phòng ban Dept","CNC Management team","Vị trí Position","Staff") -> 1 | D8: =GETPIVOTDATA("Họ và tên Full name",Sheet6!$A$3,"Phòng ban Dept","Post processing Management team","Vị trí Position","Staff") -> 5 | E8: =GETPIVOTDATA("Họ và tên Full name",Sheet6!$A$3,"Phòng ban Dept","Pro. Management team","Vị trí Position","Staff") -> 6 | F8: =GETPIVOTDATA("Họ và tên Full name",Sheet6!$A$3,"Phòng ban Dept","GA- HR Management team","Vị trí Position","Staff") -> 6 | G8: =GETPIVOTDATA("Họ và tên Full name",Sheet6!$A$3,"Phòng ban Dept","Accounting team","Vị trí Position","Staff") -> 2 | H8: =GETPIVOTDATA("Họ và tên Full name",Sheet6!$A$3,"Phòng ban Dept","Purchasing Management team PUR","Vị trí Position","Staff") -> 1 | I8: =GETPIVOTDATA("Họ và tên Full name",Sheet6!$A$3,"Phòng ban Dept","Sales Management team","Vị trí Position","Staff") -> 1 | J8: =GETPIVOTDATA("Họ và tên Full name",Sheet6!$A$3,"Phòng ban Dept","R&D Management team","Vị trí Position","Staff") -> 4 | K8: =GETPIVOTDATA("Họ và tên Full name",Sheet6!$A$3,"Phòng ban Dept","QC Management team","Vị trí Position","Staff") -> 7 | L8: =SUM(B8:K8) -> 35
A9: Technical | B9: =GETPIVOTDATA("Họ và tên Full name",Sheet6!$A$3,"Phòng ban Dept","Cast Management team","Vị trí Position","Technical ") -> 26 | C9: =GETPIVOTDATA("Họ và tên Full name",Sheet6!$A$3,"Phòng ban Dept","CNC Management team","Vị trí Position","Technical ") -> 11 | D9: =GETPIVOTDATA("Họ và tên Full name",Sheet6!$A$3,"Phòng ban Dept","Post processing Management team","Vị trí Position","Technical ") -> 18 | E9: =GETPIVOTDATA("Họ và tên Full name",Sheet6!$A$3,"Phòng ban Dept","Pro. Management team","Vị trí Position","Technical ") -> 3 | F9: =GETPIVOTDATA("Họ và tên Full name",Sheet6!$A$3,"Phòng ban Dept","GA- HR Management team","Vị trí Position","Technical ") -> 9 | G9: =GETPIVOTDATA("Họ và tên Full name",Sheet6!$A$3,"Phòng ban Dept","Accounting team","Vị trí Position","Technical ") -> 0 | H9: =GETPIVOTDATA("Họ và tên Full name",Sheet6!$A$3,"Phòng ban Dept","Purchasing Management team PUR","Vị trí Position","Technical ") -> 0 | I9: =GETPIVOTDATA("Họ và tên Full name",Sheet6!$A$3,"Phòng ban Dept","Sales Management team","Vị trí Position","Technical ") -> 0 | J9: =GETPIVOTDATA("Họ và tên Full name",Sheet6!$A$3,"Phòng ban Dept","R&D Management team","Vị trí Position","Technical ") -> 6 | K9: =GETPIVOTDATA("Họ và tên Full name",Sheet6!$A$3,"Phòng ban Dept","QC Management team","Vị trí Position","Technical ") -> 0 | L9: =SUM(B9:K9) -> 73
A10: Worker | B10: =GETPIVOTDATA("Họ và tên Full name",Sheet6!$A$3,"Phòng ban Dept","Cast Management team","Vị trí Position","Worker") -> 71 | C10: =GETPIVOTDATA("Họ và tên Full name",Sheet6!$A$3,"Phòng ban Dept","CNC Management team","Vị trí Position","Worker") -> 163 | D10: =GETPIVOTDATA("Họ và tên Full name",Sheet6!$A$3,"Phòng ban Dept","Post processing Management team","Vị trí Position","Worker") -> 184 | E10: =GETPIVOTDATA("Họ và tên Full name",Sheet6!$A$3,"Phòng ban Dept","Pro. Management team","Vị trí Position","Worker") -> 10 | F10: =GETPIVOTDATA("Họ và tên Full name",Sheet6!$A$3,"Phòng ban Dept","GA- HR Management team","Vị trí Position","Worker") -> 1 | G10: =GETPIVOTDATA("Họ và tên Full name",Sheet6!$A$3,"Phòng ban Dept","Accounting team","Vị trí Position","Worker") -> 0 | H10: =GETPIVOTDATA("Họ và tên Full name",Sheet6!$A$3,"Phòng ban Dept","Purchasing Management team PUR","Vị trí Position","Worker") -> 0 | I10: =GETPIVOTDATA("Họ và tên Full name",Sheet6!$A$3,"Phòng ban Dept","Sales Management team","Vị trí Position","Worker") -> 0 | J10: 3 | K10: =GETPIVOTDATA("Họ và tên Full name",Sheet6!$A$3,"Phòng ban Dept","QC Management team","Vị trí Position","Worker") -> 48 | L10: =SUM(B10:K10) -> 480
A11: Total | B11: =SUM(B5:B10) -> 107 | C11: =SUM(C5:C10) -> 182 | D11: =SUM(D5:D10) -> 212 | E11: =SUM(E5:E10) -> 22 | F11: =SUM(F5:F10) -> 31 | G11: =SUM(G5:G10) -> 6 | H11: =SUM(H5:H10) -> 4 | I11: =SUM(I5:I10) -> 6 | ... K11: =SUM(K5:K10) -> 66 | L11: =SUM(B11:K11) -> 660 | M11: =SUM(L5:L10) -> 660
A13: Hàn+Việt | B13: =B11+B4 -> 110 | C13: =C11+C4 -> 184 | D13: =D11+D4 -> 213 | E13: =E11+E4 -> 22 | F13: =F11+F4 -> 32 | G13: =G11+G4 -> 7 | H13: =H11+H4 -> 4 | I13: =I11+I4 -> 8 | ... L13: =L11+L4 -> 676
A14: Check | B14: =B13='17.6'!E45 -> FALSE | C14: =C13='17.6'!H45 -> FALSE | D14: ='17.6'!K45='so lieu update'!D13 -> FALSE | E14: =E13='17.6'!N45 -> FALSE | F14: =F13='17.6'!Q45 -> FALSE | G14: ='17.6'!T45='so lieu update'!G13 -> FALSE | H14: =H13='17.6'!W45 -> TRUE | I14: =I13='17.6'!Z45 -> FALSE | J14: =J13='17.6'!AC45 -> FALSE | K14: =K13='17.6'!AF45 -> FALSE | L14: =L13='17.6'!AH45 -> FALSE
